Workbook

Sheet Summary
A1: What Advanced used — GC500 2026 build (9 Sep – Fri 23 Oct 2026)
A2: From the signed papers on the GC500 Delivery Control record, read 24 Oct 2026 (record 10804). No money in this workbook.
A4: The gear (as written on the hire agreements)
A5: Mesh panels | B5: =SUM('Hire agreements'!J5:J171) -> 5223
A6: Hoarding panels | B6: =SUM('Hire agreements'!K5:K171) -> 41
A7: Feet / bases / blocks — written on the dockets | B7: =SUM('Hire agreements'!L5:L171) -> 8235 | C7: One item: feet, bases and blocks are the same thing.
A8: Clamps | B8: =SUM('Hire agreements'!M5:M171) -> 7977
A9: Braces | B9: =SUM('Hire agreements'!N5:N171) -> 1426
A10: Gate wheels | B10: =SUM('Hire agreements'!O5:O171) -> 278
A11: Crowd-control barriers | B11: =SUM('Hire agreements'!P5:P171) -> 2903
A12: Flat-feet barriers | B12: =SUM('Hire agreements'!Q5:Q171) -> 117
A14: The feet, checked against the gear
A15: Panels (mesh + hoarding) × 1 foot — shared at each join | B15: =SUM('Hire agreements'!J5:J171)+SUM('Hire agreements'!K5:K171) -> 5264 | C15: A straight run of N panels takes N + 1 feet; a closed compound takes N.
A16: Braces × 2 feet | B16: =2*SUM('Hire agreements'!N5:N171) -> 2852 | C16: Every bracing-only docket shows exactly two feet a brace (36519, 36531, 36566, 36581, 36763 …).
A17: Dropped at the iEDM compound (36600, 36620) | B17: 300 | C17: Bases only, no fence put in.
A18: Under flat-feet barriers, Club 500 (36591) | B18: 19
A19: Feet worked out from the gear | B19: =SUM(B15:B18) -> 8435 | C19: Plus one more at the open end of each straight run.
A20: Feet written on the dockets | B20: =SUM('Hire agreements'!L5:L171) -> 8235
A21: Dockets with the feet box left blank | B21: 10 | C21: 230 panels and 4 braces on them: about 240 feet not written.
A22: Feet used, about | B22: =B20+240 -> 8475 | C22: Written + the blank papers. The gear says the same.
A23: If braces actually took three feet each (not what the dockets show), add one more per brace: 1,426 more, about 9,900 in all.
A24: The 216 "fence blocks" on the page were the 216 feet on docket 36566 (108 braces at the rear of the pit building), put on the card's Fence Blocks line. They are inside the feet above, not extra concrete blocks.
A26: Metres (hire agreements, plus the reviewed service and collection papers)
A27: Temporary fence put in (clean line) | B27: =SUM('Hire agreements'!E5:E171) -> 13270 | C27: Programme was 12,617 m.
A28: Braced for scrim | B28: =SUM('Hire agreements'!F5:F171) -> 3977.5
A29: Scrim on fence already standing (service notes) | B29: 427.5
A30: Crowd control — event | B30: =SUM('Hire agreements'!G5:G171) -> 2195
A31: Crowd control — demarcation | B31: =SUM('Hire agreements'!H5:H171) -> 5062.5
A32: Flat feet | B32: =SUM('Hire agreements'!I5:I171) -> 270
A33: Relocated | B33: 612.5 | C33: Hire agreements 137.5 m + reviewed service notes 475 m (incl. 24492).
A34: Taken down and stacked | B34: 1102.5 | C34: Reviewed collection forms and service notes.
A35: Vehicle gates (docket wheels, two to a gate) | B35: 133 | C35: As the page counts them: 278 wheels on the papers, programme gates only.
A36: Pedestrian gates | B36: =SUM('Hire agreements'!S5:S171) -> 22
A38: The papers and the hours
A39: Signed hire agreements | B39: 166 | C39: Plus the Week 6 workbook row with no docket number (shown in the sheet).
A40: Service notes | B40: 42
A41: Collection forms | B41: 25
A42: Hours on service notes | B42: =SUM('Service notes'!E4:E45) -> 108.5

Sheet Hire agreements
A1: Advanced Temporary Fencing — gear used on the GC500 2026 build, docket by docket
A2: Every signed hire agreement on the record, read 24 Oct 2026 (record 10804). Quantities exactly as written on the papers. Feet, bases and blocks are the same item. Blank = not written on the paper.
A4: Date | B4: Week | C4: Docket | D4: Area (as on the docket) | E4: Fence m | F4: Scrim m | G4: CCB event m | H4: CCB demarc m | I4: Flat feet m | J4: Mesh panels | K4: Hoarding panels | L4: Feet / bases | M4: Clamps | N4: Braces | O4: Gate wheels | P4: CCB barriers | Q4: Flat-feet barriers | R4: Vehicle gates | S4: Ped gates | T4: Feet check: panels × 1 + braces × 2 | U4: Feet written less check | V4: Note
B5: CW6 · 7–12 Sep | C5: — | E5: 232.5 | R5: 3 | T5: =IF(AND(J5="",K5="",N5=""),"",N(J5)+N(K5)+2*N(N5)) | U5: =IF(OR(L5="",T5=""),"",L5-T5) | V5: Week 6 workbook row, no docket number (reads like a copy of 36501); kept as the record has it.
A6: 2026-09-09 | B6: CW6 · 7–12 Sep | C6: 36501 | D6: Sea World Drive, Main Beach | E6: 247.5 | J6: 99 | L6: 100 | M6: 118 | O6: 9 | T6: =IF(AND(J6="",K6="",N6=""),"",N(J6)+N(K6)+2*N(N6)) -> 99 | U6: =IF(OR(L6="",T6=""),"",L6-T6) -> 1
A7: 2026-09-11 | B7: CW6 · 7–12 Sep | C7: 36502 | D7: Phillip Park (Advanced compound) | E7: 257.5 | J7: 103 | L7: 101 | M7: 109 | O7: 3 | T7: =IF(AND(J7="",K7="",N7=""),"",N(J7)+N(K7)+2*N(N7)) -> 103 | U7: =IF(OR(L7="",T7=""),"",L7-T7) -> -2
A8: 2026-09-11 | B8: CW6 · 7–12 Sep | C8: 36503 | D8: Sea World Drive, Main Beach | L8: 16 | M8: 16 | N8: 8 | T8: =IF(AND(J8="",K8="",N8=""),"",N(J8)+N(K8)+2*N(N8)) -> 16 | U8: =IF(OR(L8="",T8=""),"",L8-T8) -> 0 | V8: Bracing added to fence already standing: two feet a brace.
A9: 2026-09-11 | B9: CW6 · 7–12 Sep | C9: 36504 | D9: Helen Park, BSF compound | E9: 72.5 | F9: 72.5 | J9: 29 | L9: 52 | M9: 52 | N9: 12 | O9: 2 | T9: =IF(AND(J9="",K9="",N9=""),"",N(J9)+N(K9)+2*N(N9)) -> 53 | U9: =IF(OR(L9="",T9=""),"",L9-T9) -> -1
A10: 2026-09-12 | B10: CW6 · 7–12 Sep | C10: 36511 | D10: Yatala — Morayfield (Phillip Island / Morayfield), region Yatala | T10: =IF(AND(J10="",K10="",N10=""),"",N(J10)+N(K10)+2*N(N10)) | U10: =IF(OR(L10="",T10=""),"",L10-T10)
A11: 2026-09-14 | B11: CW5 · 14–18 Sep | C11: 36505 | D11: Cypress Carpark | E11: 97.5 | J11: 39 | L11: 37 | M11: 38 | O11: 4 | T11: =IF(AND(J11="",K11="",N11=""),"",N(J11)+N(K11)+2*N(N11)) -> 39 | U11: =IF(OR(L11="",T11=""),"",L11-T11) -> -2
A12: 2026-09-14 | B12: CW5 · 14–18 Sep | C12: 36506 | D12: S18 C.2 construction zone | E12: 132.5 | F12: 10 | J12: 53 | L12: 59 | M12: 60 | N12: 4 | T12: =IF(AND(J12="",K12="",N12=""),"",N(J12)+N(K12)+2*N(N12)) -> 61 | U12: =IF(OR(L12="",T12=""),"",L12-T12) -> -2
A13: 2026-09-14 | B13: CW5 · 14–18 Sep | C13: 36507 | D13: Admiralty Drive — crossing closure | E13: 7.5 | J13: 3 | L13: 4 | M13: 2 | T13: =IF(AND(J13="",K13="",N13=""),"",N(J13)+N(K13)+2*N(N13)) -> 3 | U13: =IF(OR(L13="",T13=""),"",L13-T13) -> 1
A14: 2026-09-14 | B14: CW5 · 14–18 Sep | C14: 36508 | D14: P.B03 C.2 | E14: 20 | J14: 8 | L14: 8 | M14: 8 | T14: =IF(AND(J14="",K14="",N14=""),"",N(J14)+N(K14)+2*N(N14)) -> 8 | U14: =IF(OR(L14="",T14=""),"",L14-T14) -> 0
A15: 2026-09-14 | B15: CW5 · 14–18 Sep | C15: 36509 | D15: Pit Building / Paddock C.2 — perimeter fencing | E15: 577.5 | J15: 231 | L15: 221 | M15: 233 | O15: 16 | S15: 2 | T15: =IF(AND(J15="",K15="",N15=""),"",N(J15)+N(K15)+2*N(N15)) -> 231 | U15: =IF(OR(L15="",T15=""),"",L15-T15) -> -10
A16: 2026-09-14 | B16: CW5 · 14–18 Sep | C16: 36510 | D16: Sea World Drive, Main Beach | T16: =IF(AND(J16="",K16="",N16=""),"",N(J16)+N(K16)+2*N(N16)) | U16: =IF(OR(L16="",T16=""),"",L16-T16)
A17: 2026-09-14 | B17: CW5 · 14–18 Sep | C17: 36512 | D17: S04 Corporate Facility / TV compound | E17: 172.5 | J17: 69 | L17: 68 | M17: 68 | O17: 6 | T17: =IF(AND(J17="",K17="",N17=""),"",N(J17)+N(K17)+2*N(N17)) -> 69 | U17: =IF(OR(L17="",T17=""),"",L17-T17) -> -1
A18: 2026-09-15 | B18: CW5 · 14–18 Sep | C18: 36513 | D18: S07 C-Zone | E18: 127.5 | F18: 12.5 | J18: 51 | L18: 60 | M18: 60 | N18: 5 | O18: 2 | T18: =IF(AND(J18="",K18="",N18=""),"",N(J18)+N(K18)+2*N(N18)) -> 61 | U18: =IF(OR(L18="",T18=""),"",L18-T18) -> -1
A19: 2026-09-15 | B19: CW5 · 14–18 Sep | C19: 36514 | D19: Event Operations — iEDM compound | E19: 147.5 | F19: 70 | J19: 59 | L19: 116 | M19: 172 | N19: 28 | O19: 6 | S19: 1 | T19: =IF(AND(J19="",K19="",N19=""),"",N(J19)+N(K19)+2*N(N19)) -> 115 | U19: =IF(OR(L19="",T19=""),"",L19-T19) -> 1
A20: 2026-09-15 | B20: CW5 · 14–18 Sep | C20: 36515 | D20: S07 — hill protection | G20: 60 | P20: 24 | T20: =IF(AND(J20="",K20="",N20=""),"",N(J20)+N(K20)+2*N(N20)) | U20: =IF(OR(L20="",T20=""),"",L20-T20)
A21: 2026-09-15 | B21: CW5 · 14–18 Sep | C21: 36516 | D21: Track storage | E21: 87.5 | J21: 35 | L21: 35 | M21: 35 | O21: 2 | T21: =IF(AND(J21="",K21="",N21=""),"",N(J21)+N(K21)+2*N(N21)) -> 35 | U21: =IF(OR(L21="",T21=""),"",L21-T21) -> 0
A22: 2026-09-16 | B22: CW5 · 14–18 Sep | C22: 36517 | D22: S.O.5 C.2 | E22: 67.5 | J22: 27 | L22: 25 | M22: 25 | O22: 2 | T22: =IF(AND(J22="",K22="",N22=""),"",N(J22)+N(K22)+2*N(N22)) -> 27 | U22: =IF(OR(L22="",T22=""),"",L22-T22) -> -2
A23: 2026-09-16 | B23: CW5 · 14–18 Sep | C23: 36518 | D23: S.O.5 — grandstand, back of house | E23: 35 | F23: 22.5 | J23: 14 | L23: 31 | M23: 30 | N23: 9 | O23: 2 | T23: =IF(AND(J23="",K23="",N23=""),"",N(J23)+N(K23)+2*N(N23)) -> 32 | U23: =IF(OR(L23="",T23=""),"",L23-T23) -> -1
A24: 2026-09-16 | B24: CW5 · 14–18 Sep | C24: 36519 | D24: Event operations — iEDM compound | F24: 72.5 | L24: 58 | M24: 58 | N24: 29 | T24: =IF(AND(J24="",K24="",N24=""),"",N(J24)+N(K24)+2*N(N24)) -> 58 | U24: =IF(OR(L24="",T24=""),"",L24-T24) -> 0 | V24: Bracing added to fence already standing: two feet a brace.
A25: 2026-09-16 | B25: CW5 · 14–18 Sep | C25: 36520 | D25: Coates compound / ABD compound | E25: 112.5 | F25: 40 | J25: 45 | L25: 75 | M25: 76 | N25: 16 | O25: 4 | T25: =IF(AND(J25="",K25="",N25=""),"",N(J25)+N(K25)+2*N(N25)) -> 77 | U25: =IF(OR(L25="",T25=""),"",L25-T25) -> -2
A26: 2026-09-16 | B26: CW5 · 14–18 Sep | C26: 36521 | D26: S.O.8 exclusion zone | E26: 27.5 | J26: 11 | L26: 10 | M26: 10 | T26: =IF(AND(J26="",K26="",N26=""),"",N(J26)+N(K26)+2*N(N26)) -> 11 | U26: =IF(OR(L26="",T26=""),"",L26-T26) -> -1
A27: 2026-09-16 | B27: CW5 · 14–18 Sep | C27: 36522 | D27: Triangles mound, green bays — Macintosh Island Park | G27: 277.5 | P27: 111 | T27: =IF(AND(J27="",K27="",N27=""),"",N(J27)+N(K27)+2*N(N27)) | U27: =IF(OR(L27="",T27=""),"",L27-T27)
A28: 2026-09-17 | B28: CW5 · 14–18 Sep | C28: 36523 | D28: Helen Park — BSF compound | F28: 22.5 | L28: 18 | M28: 18 | N28: 18 | T28: =IF(AND(J28="",K28="",N28=""),"",N(J28)+N(K28)+2*N(N28)) -> 36 | U28: =IF(OR(L28="",T28=""),"",L28-T28) -> -18 | V28: Bracing added to fence already standing: two feet a brace.
A29: 2026-09-17 | B29: CW5 · 14–18 Sep | C29: 36524 | D29: Race admin | E29: 137.5 | J29: 55 | L29: 129 | M29: 128 | N29: 38 | O29: 4 | T29: =IF(AND(J29="",K29="",N29=""),"",N(J29)+N(K29)+2*N(N29)) -> 131 | U29: =IF(OR(L29="",T29=""),"",L29-T29) -> -2
A30: 2026-09-17 | B30: CW5 · 14–18 Sep | C30: 36525 | D30: S.O.5 C.2 | T30: =IF(AND(J30="",K30="",N30=""),"",N(J30)+N(K30)+2*N(N30)) | U30: =IF(OR(L30="",T30=""),"",L30-T30)
A31: 2026-09-17 | B31: CW5 · 14–18 Sep | C31: 36526 | D31: S.O.5 — retaining wall | E31: 10 | J31: 4 | L31: 4 | M31: 3 | T31: =IF(AND(J31="",K31="",N31=""),"",N(J31)+N(K31)+2*N(N31)) -> 4 | U31: =IF(OR(L31="",T31=""),"",L31-T31) -> 0
A32: 2026-09-17 | B32: CW5 · 14–18 Sep | C32: 36528 | D32: S.O.8 exclusion zone | O32: 2 | T32: =IF(AND(J32="",K32="",N32=""),"",N(J32)+N(K32)+2*N(N32)) | U32: =IF(OR(L32="",T32=""),"",L32-T32)
A33: 2026-09-17 | B33: CW5 · 14–18 Sep | C33: 36529 | D33: P.B.03 | E33: 45 | F33: 10 | J33: 18 | M33: 17 | N33: 4 | T33: =IF(AND(J33="",K33="",N33=""),"",N(J33)+N(K33)+2*N(N33)) -> 26 | U33: =IF(OR(L33="",T33=""),"",L33-T33) | V33: Feet box left blank on the paper.
A34: 2026-09-17 | B34: CW5 · 14–18 Sep | C34: 36530 | D34: PB01 works area | E34: 15 | G34: 50 | J34: 6 | L34: 6 | M34: 6 | P34: 20 | T34: =IF(AND(J34="",K34="",N34=""),"",N(J34)+N(K34)+2*N(N34)) -> 6 | U34: =IF(OR(L34="",T34=""),"",L34-T34) -> 0
A35: 2026-09-17 | B35: CW5 · 14–18 Sep | C35: 36531 | D35: Pit building paddock | F35: 105 | L35: 84 | M35: 84 | N35: 42 | T35: =IF(AND(J35="",K35="",N35=""),"",N(J35)+N(K35)+2*N(N35)) -> 84 | U35: =IF(OR(L35="",T35=""),"",L35-T35) -> 0 | V35: Bracing added to fence already standing: two feet a brace.
A36: 2026-09-18 | B36: CW5 · 14–18 Sep | C36: 36532 | D36: S10 compound | E36: 150 | F36: 132.5 | J36: 60 | L36: 164 | M36: 162 | N36: 53 | O36: 2 | T36: =IF(AND(J36="",K36="",N36=""),"",N(J36)+N(K36)+2*N(N36)) -> 166 | U36: =IF(OR(L36="",T36=""),"",L36-T36) -> -2
A37: 2026-09-18 | B37: CW5 · 14–18 Sep | C37: 36533 | D37: S10 C.2 | E37: 45 | J37: 18 | L37: 18 | M37: 14 | O37: 2 | T37: =IF(AND(J37="",K37="",N37=""),"",N(J37)+N(K37)+2*N(N37)) -> 18 | U37: =IF(OR(L37="",T37=""),"",L37-T37) -> 0
A38: 2026-09-18 | B38: CW5 · 14–18 Sep | C38: 36534 | D38: S10 to pit entry | H38: 235 | P38: 94 | T38: =IF(AND(J38="",K38="",N38=""),"",N(J38)+N(K38)+2*N(N38)) | U38: =IF(OR(L38="",T38=""),"",L38-T38)
A39: 2026-09-18 | B39: CW5 · 14–18 Sep | C39: 36535 | D39: S10 to pedestrian bridge | H39: 30 | P39: 12 | T39: =IF(AND(J39="",K39="",N39=""),"",N(J39)+N(K39)+2*N(N39)) | U39: =IF(OR(L39="",T39=""),"",L39-T39)
A40: 2026-09-21 | B40: CW4 · 21–25 Sep | C40: 36536 | D40: S08 C.Z. — construction zone | E40: 172.5 | J40: 69 | L40: 72 | M40: 70 | O40: 2 | T40: =IF(AND(J40="",K40="",N40=""),"",N(J40)+N(K40)+2*N(N40)) -> 69 | U40: =IF(OR(L40="",T40=""),"",L40-T40) -> 3
A41: 2026-09-21 | B41: CW4 · 21–25 Sep | C41: 36537 | D41: S04 C.Z. — construction zone | E41: 172.5 | J41: 69 | L41: 71 | M41: 70 | O41: 2 | T41: =IF(AND(J41="",K41="",N41=""),"",N(J41)+N(K41)+2*N(N41)) -> 69 | U41: =IF(OR(L41="",T41=""),"",L41-T41) -> 2
...

Sheet Service notes
A1: Service notes (green book) — labour and work on fence already standing
A3: Date | B3: Week | C3: Note | D3: Area | E3: Hours | F3: Metres | G3: Crew, as written | H3: What the note says
A4: 2026-09-15 | B4: CW5 · 14–18 Sep | C4: 24451 | D4: Advanced compound — Phillip Island | E4: 0.5 | G4: 1 man x 1 truck, half an hour | H4: Written on the note: unloaded semi at 11:00, completed 11:30 (Raceview).
A5: 2026-09-15 | B5: CW5 · 14–18 Sep | C5: 24452 | D5: Advanced compound — Phillip Island | E5: 0.5 | G5: 1 man x 1 truck, half an hour | H5: Written on the note: unloaded semi 11:30 to 12:00, completed.
A6: 2026-09-16 | B6: CW5 · 14–18 Sep | C6: 24453 | D6: Advanced compound — Phillip Park | E6: 1.5 | H6: Written on the note: truck 1 11:30–12:00 = 0.5 h; truck 2 12:00–12:30 = 0.5 h; truck 3 12:30–12:45 with 2 men, 0.25 x 2 = 0.5 h. Three truck loads, 1.5 hours in total — the note’s own arithmetic, not ours.
A7: 2026-09-17 | B7: CW5 · 14–18 Sep | C7: 24454 | D7: Advanced compound — Phillip Park | E7: 1 | H7: Written on the note: truck 1 12:15–12:45 (1 person); truck 2 13:30–14:00. One hour.
A8: 2026-09-18 | B8: CW5 · 14–18 Sep | C8: 24455 | D8: Truck storage | E8: 0.75 | G8: 3 men x 15 minutes each = 0.75 hours | H8: Written on the note: STACKED DOWN the rear section of fence as requested by iEDM, 32.5 m. This is fence COMING DOWN, not going in, and the 2026 card has NO removal line — so the 32.5 m is on the record and is not costed until the project manager says how a stack-down is charged. It also reads on the wording of hire agreement 36530 ("struck down"), which may be the same kind of work — his call. Cor
A9: 2026-09-21 | B9: CW4 · 21–25 Sep | C9: 24456 | D9: Truck storage | E9: 0.75 | G9: 3 men x 15 minutes each = 0.75 hours | H9: Written on the note: re-installed the stacked-down panels along the rear section, 32.5 m — the 32.5 m stacked down at iEDM’s request on 18 Sep (note 24455).
A10: 2026-09-21 | B10: CW4 · 21–25 Sep | C10: 24457 | D10: Advanced compound — Phillip Park | E10: 1 | G10: 1 man x 1 hr | H10: Written on the note: unload semis — truck 1 10:30am–11:00am, truck 2 12:00pm–12:30pm, 1 hr total. The date reads 21/09/26 at the head and beside the installer’s signature.
A11: 2026-09-23 | B11: CW4 · 21–25 Sep | C11: 24458 | D11: Advanced compound — Phillip Park | E11: 1 | G11: 1 man x 1 hr | H11: Written on the note: unload semis — trucks 849 VAH 11:30am–12:00pm and XB 701V 12:00pm–12:30pm.
A12: 2026-09-24 | B12: CW4 · 21–25 Sep | C12: 24459 | D12: Advanced compound — Phillip Park | E12: 1.5 | G12: 1 man x 1.5 hrs | H12: Written on the note: unload semis — trucks XQ 39GD 1:00pm–1:30pm, XQ 82PV 2:00pm–2:30pm and XC 71GI 3:15pm–3:45pm.
A13: 2026-09-25 | B13: CW4 · 21–25 Sep | C13: 24460 | D13: S08 C.Z. — relocation | E13: 1 | G13: 2 men x 30 mins each | H13: Written on the note: 40 m relocation. Labour 1 hr (2 men x 30 mins each).
A14: 2026-09-29 | B14: CW3 · 28 Sep–2 Oct | C14: 24461 | D14: S08 construction zone | E14: 1 | F14: 32.5 | G14: 4 men x 15 mins each | H14: 32.5 m relocated to the stair entrance and run along the rear of the grandstand
A15: 2026-09-29 | B15: CW3 · 28 Sep–2 Oct | C15: 24462 | D15: S08 construction zone / beach install | E15: 2 | F15: 100 | G15: 4 men x 30 mins each | H15: 100 m relocated from S08 construction zone to the beach run install
A16: 2026-09-30 | B16: CW3 · 28 Sep–2 Oct | C16: 24463 | D16: S04 BOH | E16: 0.75 | F16: 17.5 | G16: 3 men x 15 mins each | H16: Written on the note: relocate 17.5 m of temp fence to the other side of the timber bollard. Relocation scope only; no new hire metres. Owner sign-off: Andrew, 2 Oct 2026; work/installation date: 2026-09-30. Prices and totals are blank on the photographed paper; the existing tracker labour rate is applied by the page.
A17: 2026-09-30 | B17: CW3 · 28 Sep–2 Oct | C17: 24464 | D17: Advanced compound - Phillip Park (written "Phillip Island") | E17: 1 | G17: Labour 1 man x 1 hr (the Labour and Travel lines are crossed out and rewritten) | H17: Written on the note: truck XQ39GD 09:45-10:15 and truck XB38ZP 10:30-11:00. The Labour/Travel labels were crossed out and rewritten as Labour 1 man x 1 hr. The written site is Phillip Island; mapped to the Advanced compound at Phillip Park as recorded in the handover. No separate travel entry; unloading/semis is contextual wording in the handover, not a clean original transcription. Owner sign-off
A18: 2026-10-01 | B18: CW3 · 28 Sep–2 Oct | C18: 24465 | D18: Phillip Park - Advanced compound | E18: 1 | G18: 2 men x 30 mins each (1 hr) | H18: Written on the note: 1 hr; rego 1 best read XQ37UH, rego 2 best read XQ70IV (handwriting partly unclear; see original). One hour total, not two. Installer signature/date fields are blank. Owner sign-off: Andrew, 2 Oct 2026; work/installation date: 2026-10-01. Prices and totals are blank on the photographed paper; the existing tracker labour rate is applied by the page.
A19: 2026-10-02 | B19: CW3 · 28 Sep–2 Oct | C19: 24466 | D19: Telstra COW | E19: 0.5 | F19: 25 | G19: 2 men x 15 mins each (0.5 hr) | H19: Written on the note: Labour "2 men x 15 mins each", quantity 0.5 hrs. Notes: "Scrim 25m". Installer signature present. Prices and totals are blank; the tracker labour rate is applied by the page.
A20: 2026-10-02 | B20: CW3 · 28 Sep–2 Oct | C20: 24467 | D20: Phillip Park - Advanced compound | E20: 0.25 | G20: 1 man x 15 mins (0.25 hr) | H20: Written on the note: Labour "1 man x 15 mins", quantity 0.25 hrs. Notes: "XC 03EK - 13:30 to 13:45" (a rego and the time, best read; as 24465 recorded regos). Installer signature present. Prices and totals are blank; the tracker labour rate is applied by the page.
A21: 2026-10-06 | B21: CW2 · 6–9 Oct | C21: 24468 | D21: Phillip Park — Advanced compound | E21: 0.25 | G21: 1 man × 15 mins | H21: Truck identifier followed by 1:15 pm–1:30 pm. Work date from the paper; owner signed 8 Oct 2026. Prices and totals are blank; existing GC500 card and supplier rates apply where quantities are chargeable. Original signed paper 24468.jpg.
A22: 2026-10-06 | B22: CW2 · 6–9 Oct | C22: 24469 | D22: S04 Corporate — fence relocation | E22: 0.75 | F22: 17.5 | G22: 3 men × 15 mins each | H22: Relocate 17.5 m temporary fence. Work date from the paper; owner signed 8 Oct 2026. Prices and totals are blank; existing GC500 card and supplier rates apply where quantities are chargeable. Original signed paper 24469.jpg.
A23: 2026-10-07 | B23: CW2 · 6–9 Oct | C23: 24470 | D23: Phillip Park — Advanced compound | E23: 1.5 | G23: 1 man × 90 mins | H23: Three truck windows: Truck 1 10:15–10:45; Truck 2 11:45–12:15; Truck 3 12:30–13:00. Work date from the paper; owner signed 8 Oct 2026. Prices and totals are blank; existing GC500 card and supplier rates apply where quantities are chargeable. Original signed paper 24470.jpg.
A24: 2026-10-07 | B24: CW2 · 6–9 Oct | C24: 24471 | D24: S04 to S05 — CCBs | E24: 1.5 | F24: 65 | G24: 6 men × 15 mins each | H24: Relocate 65 m CCBs; trailing purpose/location is faint and appears to refer to S05 Bar. Work date from the paper; owner signed 8 Oct 2026. Prices and totals are blank; existing GC500 card and supplier rates apply where quantities are chargeable. Original signed paper 24471.jpg.
A25: 2026-10-07 | B25: CW2 · 6–9 Oct | C25: 24472 | D25: S10 | E25: 4 | F25: 150 | G25: 4 men × 1 hr each | H25: Scrim 150 m temp fence. This is scrim work, not evidence of a further 150 m new mesh fence. Work date from the paper; owner signed 8 Oct 2026. Prices and totals are blank; existing GC500 card and supplier rates apply where quantities are chargeable. Original signed paper 24472.jpg. Scrim work relates to the existing S10 fence (hire agreement 36532 / F031); it does not add another 150 m of mesh or
A26: 2026-10-08 | B26: CW2 · 6–9 Oct | C26: 24473 | D26: Pit Lane | E26: 4 | F26: 150 | G26: 4 men × 1 hour each | H26: Scrim existing fence — 150 m. Work/installer dated 8 Oct; owner signed 9 Oct. Existing-fence work; no new mesh length inferred. Exact earlier hire agreement not identified by this paper; source-linked scrim quantity remains for reconciliation.
A27: 2026-10-09 | B27: CW2 · 6–9 Oct | C27: 24474 | D27: Race Admin — Double Stack CZ relocation | E27: 0.5 | F27: 25 | G27: 2 men × 15 minutes each | H27: Relocate 25 m. Labour quantity 0.5 hours. Collection 28555 also names Race Admin Double Stack CZ but is a separate collected-count record; no extra hire or removal metres inferred.
A28: 2026-10-12 | B28: CW1 · 12–16 Oct | C28: 24475 | D28: Maddison Point to Ferny Ave | E28: 3 | F28: 135 | G28: 1/2 hr x 6 men | H28: Had to walk panels in from Maddison Point to Ferny Ave. Hire agreement invoice num 36596. No access for truck: concrete bollards already installed. Metres installed 135 metres (explanatory note on this labour service sheet).
A29: 2026-10-12 | B29: CW1 · 12–16 Oct | C29: 24478 | D29: Philip Park - Advanced Compound | E29: 0.5 | G29: 1 man x 0.5 hr | H29: XB60AQ - 13:45 - 14:15
A30: 2026-10-13 | B30: CW1 · 12–16 Oct | C30: 24476 | D30: Helen Park | E30: 2 | F30: 82.5 | G30: 1/2 hr - 4 men | H30: Scrim existing fence. 82.5 m.
A31: 2026-10-13 | B31: CW1 · 12–16 Oct | C31: 24477 | D31: S.0.2 - B.O.H. | E31: 1.5 | F31: 75 | G31: 15 mins x 6 men | H31: Scrim existing fence - 75 m.
A32: 2026-10-13 | B32: CW1 · 12–16 Oct | C32: 24479 | D32: Philip Park - Advanced Compound | E32: 0.5 | G32: 1 man x 0.5 hrs | H32: XB38ZP 12:15 - 12:45
A33: 2026-10-14 | B33: CW1 · 12–16 Oct | C33: 24480 | D33: Philip Park - Advanced Compound | E33: 1.5 | G33: 1 man x 1 hr + 2 men x 0.25 hr each | H33: XB77VR 9:45 - 10:15; 771CIK 10:15 - 10:45; 22CIRA 13:00 - 13:15 - 2 men x 0.25 hr each
A34: 2026-10-15 | B34: CW1 · 12–16 Oct | C34: 24481 | D34: S.0.8 B.O.H. | E34: 4 | F34: 65 | G34: 1 hr x 4 men | H34: Includes relocation of S08 CZ to S08 BOH: 65 m. Also includes 120 m scrim, a separate activity. Hire agreement docket number 36614. Labour: 1 hr x 4 men = 4 person-hours. Original source-zone glyph resembles C.Z./C.2.; normalised as construction zone. The earlier metres value 185 combined relocation and scrim; the Metres moved field now retains only the written 65 m relocation.
A35: 2026-10-19 | B35: Event week · 19–23 Oct | C35: 24482 | D35: Admiralty Dr - intersection | E35: 1.25 | G35: see notes: 2 men x 15 min and 3 men x 15 min | H35: Relocations at the Admiralty Dr intersection on 19 Oct 2026: 'Relocate 22.5 m temp fence - 2 men x 15 mins each = 0.5 hrs' and 'Relocate 70 m CCBs - 3 men x 15 mins each = 0.75 hrs', 1.25 h in the Labour quantity box. Two words at the start of the site address are scribbled out; a word in the notes is crossed out. Hire agreement 36624 is the same day's fence here. Owner/site supervisor and install
A36: 2026-10-20 | B36: Event week · 19–23 Oct | C36: 24483 | D36: S04 BOH / corporate entry | E36: 1 | F36: 17.5 | G36: 2 men x 30 min each | H36: 'Relocate 17.5 m temporary fence' at the S04 back-of-house / corporate entry on 20 Oct 2026; the '1 hr' sits one row above the Labour row on the paper (in the Supply Hardwood Stakes quantity cell) beside the crew note '2 men x 30 min each'. Both signatures dated 20/10/26.
A37: 2026-10-20 | B37: Event week · 19–23 Oct | C37: 24484 | D37: Helen Park | E37: 2 | F37: 80 | G37: 1/2 hr, 4 men | H37: 'Relocated panels from Helen Park C.Z to B.O.H. Braced & Scrim (tick). 80 m' on 20 Oct 2026, 2 h (half an hour, four men). Explicitly recorded metres: 80 m of relocated fence braced and scrimmed at the Helen Park back of house - the scrim on it is not charged from this note; it sits with hire agreement 36629 of the same day (the braces) for Andrew's word through the page's reviewed scrim path. Bot
A38: 2026-10-20 | B38: Event week · 19–23 Oct | C38: 24485 | D38: Pit Lane - Race Admin - BOH - TV/Media - S04 | E38: 8 | G38: 4 hrs x 2 men | H38: 8 h (4 hours, two men) on 20 Oct 2026 across Pit Lane, Race Admin, back of house, TV/Media and S04; the notes list 'Race Admin 122.5 m', 'Pit Lane - 22.5 m', 'B.O.H - TV Media - S04 - 137.5 m' (282.5 m in all) without saying what was done to them - no metres recorded on the note's own line for that reason. A word in the Postal Address row is scribbled out. Both signatures dated 20/10/26.
A39: 2026-10-20 | B39: Event week · 19–23 Oct | C39: 24486 | D39: Creek protection to Club 500 | E39: 0.5 | G39: 15 mins, 2 men | H39: 'Relocation' from the creek protection to Club 500, half an hour (15 minutes, two men). The installation date is blank and the installer signature and date are blank; the owner/site supervisor signed and dated it 20/10/26, which is the date recorded. No metres on the paper.
A40: 2026-10-21 | B40: Event week · 19–23 Oct | C40: 24489 | D40: Philip Park - Advanced compound | E40: 0.5 | G40: 2 men x 15 min each | H40: Half an hour (two men, 15 minutes each) at the Philip Park Advanced compound on 21 Oct 2026; the note reads 'Truck - PB17x' followed by a scribble (as best read). Both signatures dated 21/10/26.
A41: 2026-10-22 | B41: Event week · 19–23 Oct | C41: 24487 | D41: Track wide - scrim labour | E41: 31.5 | F41: 745 | G41: 3 men - 10.5 hrs (8 am - 6:30 pm) | H41: 'Scrim labour' on 22 Oct 2026, 31.5 h (three men, 10.5 hours, 8 am to 6:30 pm): 'Porsche to Staghorn St - 420 m' and 'S04 / Podium / S01 Kitchen = 325 m' (745 m in all, the metres recorded). The scrim on these existing fences is not charged from this note: Porsche to Staghorn St is the Esplanade fence that 36644 braced (components only) and the podium's own paper 36631 carries its 5 m of scrim; th
...

Sheet Collections
A1: Collection forms (blue book) — gear collected back off site
A3: Date | B3: Week | C3: Form | D3: Area | E3: Mesh panels | F3: Feet / bases | G3: Clamps | H3: Braces | I3: Gate wheels | J3: CCB barriers | K3: Flat-feet barriers | L3: Ped gates | M3: What the form says
A4: 2026-09-21 | B4: CW4 · 21–25 Sep | C4: 28551 | D4: S.O.8 exclusion zone | E4: 11 | F4: 10 | G4: 10 | M4: Collection form / charge sheet, removal date 21/9/26. Written: 11 mesh panels, 10 bases and 10 clamps collected. The number issued, the difference, the agreed cost and sub-total columns and the hire agreement number box are all blank, so nothing is priced or charged from it. Its counts are exactly t
A5: 2026-09-25 | B5: CW4 · 21–25 Sep | C5: 28552 | D5: S07 C.Z. | E5: 47 | F5: 58 | G5: 58 | H5: 5 | M5: Collection form / charge sheet, removal date 25/9/26. Written: 47 mesh panels, 58 bases, 58 clamps, 5 braces collected. In the mesh panels issued box a figure is scribbled out; nothing else is written in the issued column. Comment on the form: left +4 panels to secure stair way. The difference, agre
A6: 2026-09-25 | B6: CW4 · 21–25 Sep | C6: 28553 | D6: S.O.8 C.Z. | E6: 20 | F6: 27 | G6: 23 | M6: Collection form / charge sheet, removal date 25/9/26. Written: 20 mesh panels, 27 bases, 23 clamps collected. The difference, agreed cost and sub-total columns and the hire agreement number box are blank, so nothing is priced or charged from it.
A7: 2026-10-06 | B7: CW2 · 6–9 Oct | C7: 28554 | D7: S04 Corporate | E7: 26 | F7: 29 | G7: 29 | M7: Values are in NO. COLLECTED: 26 mesh panels, 29 bases, 29 clamps. Hire agreement number, removal time and all costs are blank. No removal length is written. Removal date 6 Oct 2026; owner signed 8 Oct 2026. Original signed collection form 28554.jpg. No charge or credit inferred.
A8: 2026-10-09 | B8: CW2 · 6–9 Oct | C8: 28555 | D8: Race Admin — Double Stack CZ | E8: 3 | F8: 3 | G8: 3 | M8: Collected quantities as written. Hire agreement and issued counts blank; no charge, credit or metres inferred.
A9: 2026-10-09 | B9: CW2 · 6–9 Oct | C9: 28556 | D9: Pit Lane Storage | E9: 38 | F9: 36 | G9: 38 | M9: Collected quantities as written. Hire agreement and issued counts blank; no charge, credit or metres inferred.
A10: 2026-10-12 | B10: CW1 · 12–16 Oct | C10: 28557 | D10: Double Stack CZ | E10: 30 | F10: 28 | G10: 28 | I10: 2 | M10: Collected quantities as written. Original location reads Double stack - C.Z. (final handwritten glyph resembles 2); normalised as construction zone. The supplied commercial programme prints 28857, while this original is 28557, with matching 12 Oct Double Stack removal scope; both references are pres
A11: 2026-10-15 | B11: CW1 · 12–16 Oct | C11: 28558 | D11: Pit Lane | E11: 84 | F11: 86 | G11: 84 | I11: 2 | M11: Collected quantities as written. Hire agreement and issued counts blank; no charge, credit or metres inferred.
A12: 2026-10-15 | B12: CW1 · 12–16 Oct | C12: 28559 | D12: Porsche Lounge | E12: 12 | F12: 10 | G12: 13 | M12: Collected quantities as written. Hire agreement and issued counts blank; no charge, credit or metres inferred.
A13: 2026-10-15 | B13: CW1 · 12–16 Oct | C13: 28560 | D13: S18 - Grandstand | E13: 6 | F13: 6 | G13: 5 | M13: Collected quantities as written. Hire agreement and issued counts blank; no charge, credit or metres inferred.
A14: 2026-10-19 | B14: Event week · 19–23 Oct | C14: 28561 | D14: Oceanway C.Z. | E14: 34 | F14: 34 | G14: 34 | I14: 2 | M14: Collected from Oceanway C.Z.: 34 mesh panels, 34 bases, 34 clamps, 2 wheels. Removal date written 19/10/26. No hire agreement number, order number or removal time written; no comments; nothing priced on the form. The owner/site supervisor's signature is dated 22/10/26, the installer's 19/10/26.
A15: 2026-10-20 | B15: Event week · 19–23 Oct | C15: 28562 | D15: Pit Building B.O.H. | J15: 7 | M15: Collected from Pit Building B.O.H.: 7 CC barriers. Removal date written 20/10/26. No hire agreement number, order number or removal time written; no comments; nothing priced on the form. The owner/site supervisor's signature is dated 22/10/26, the installer's 20/10/26. 'Scott.' is written below the
A16: 2026-10-20 | B16: Event week · 19–23 Oct | C16: 28563 | D16: S.O.4 – C.Z. | E16: 5 | F16: 4 | G16: 8 | I16: 1 | M16: Collected from S.O.4 – C.Z.: 5 mesh panels, 4 bases, 8 clamps, 1 wheel. Removal date written 20/10/26. No hire agreement number, order number or removal time written; no comments; nothing priced on the form. The owner/site supervisor's signature is dated 22/10/26, the installer's 20/10/26.
A17: 2026-10-20 | B17: Event week · 19–23 Oct | C17: 28564 | D17: Medium strip – North – C.Z. | E17: 5 | F17: 4 | G17: 4 | L17: 1 | M17: Collected from the median strip north C.Z. (written 'Medium strip – North – C.Z.'): 5 mesh panels, 4 bases, 4 clamps, 1 pedestrian gate. Removal date written 20/10/26. No hire agreement number, order number or removal time written; no comments; nothing priced on the form. The owner/site supervisor's
A18: 2026-10-21 | B18: Event week · 19–23 Oct | C18: 28566 | D18: Porsche C.Z. | E18: 12 | F18: 13 | G18: 10 | I18: 4 | M18: Collected from the Porsche C.Z.: 12 mesh panels, 13 bases, 10 clamps, 4 wheels. Removal date written 21/10/26 (the owner/site supervisor's signature is dated 20/10/26, the installer's 21/10/26). No hire agreement number written; no comments.
A19: 2026-10-21 | B19: Event week · 19–23 Oct | C19: 28567 | D19: Triangle C.Z. | E19: 31 | F19: 27 | G19: 28 | I19: 2 | M19: Collected from the Triangle C.Z.: 31 mesh panels, 27 bases, 28 clamps, 2 wheels. Removal date written 21/10/26 (the owner/site supervisor's signature is dated 20/10/26, the installer's 21/10/26). No hire agreement number written; no comments.
A20: 2026-10-21 | B20: Event week · 19–23 Oct | C20: 28569 | D20: S15 - C.Z. | E20: 38 | F20: 39 | G20: 37 | I20: 2 | M20: Collected 21 Oct 2026 from the S15 C.Z.: 38 mesh panels, 39 bases, 37 clamps, 2 wheels. No hire agreement number written; no comments. Both signatures dated 21/10/26.
A21: 2026-10-21 | B21: Event week · 19–23 Oct | C21: 28570 | D21: Club 500 - creek protection zone | F21: 19 | K21: 19 | M21: Collected 21 Oct 2026 from the Club 500 creek protection zone: 19 bases and, on a handwritten row, 19 flat-feet CCBs. No hire agreement number written; no comments. Both signatures dated 21/10/26.
A22: 2026-10-22 | B22: Event week · 19–23 Oct | C22: 28571 | D22: The Hill - Monster C.Z. | E22: 59 | F22: 53 | G22: 53 | I22: 2 | M22: Collected from the Monster Energy C.Z. on The Hill: 59 mesh panels, 53 bases, 53 clamps, 2 wheels. Removal date written 22/10/26 (the owner/site supervisor's signature is dated 21/10/26, the installer's 22/10/26). No hire agreement number written; no comments.
A23: 2026-10-22 | B23: Event week · 19–23 Oct | C23: 28572 | D23: PB03 | E23: 4 | M23: Collected 22 Oct 2026 from PB03: 4 mesh panels; Base and Clamp written as a dash - none. No hire agreement number written; no comments. Both signatures dated 22/10/26.
A24: 2026-10-22 | B24: Event week · 19–23 Oct | C24: 28574 | D24: Macintosh Island - Pit Building north | J24: 1 | K24: 16 | M24: Collected 22 Oct 2026 from Macintosh Island - Pit Building north: 1 CC barrier and, on a handwritten row, 16 flat-feet CCBs. No hire agreement number written; no comments. Both signatures dated 22/10/26.
A25: 2026-10-22 | B25: Event week · 19–23 Oct | C25: 28575 | D25: Macintosh Island | E25: 2 | M25: Collected 22 Oct 2026 from Macintosh Island: 2 mesh panels; Base and Clamp written as a dash - none. No hire agreement number written; no comments. Both signatures dated 22/10/26.
A26: 2026-10-22 | B26: Event week · 19–23 Oct | C26: 28577 | D26: S19 | E26: 4 | F26: 3 | G26: 3 | J26: 15 | M26: Collected 22 Oct 2026 from S19: 4 mesh panels, 15 CC barriers, 3 bases, 3 clamps. No hire agreement number written; no comments. Both signatures dated 22/10/26.
A27: 2026-10-22 | B27: Event week · 19–23 Oct | C27: 28578 | D27: S21 | E27: 4 | F27: 2 | G27: 6 | I27: 2 | J27: 22 | M27: Collected 22 Oct 2026 from S21: 4 mesh panels, 22 CC barriers, 2 bases, 6 clamps, 2 wheels. No hire agreement number written; no comments. Both signatures dated 22/10/26.
A28: 2026-10-22 | B28: Event week · 19–23 Oct | C28: 28579 | D28: Monster Energy C.Z. | E28: 1 | M28: Collected 22 Oct 2026 from the Monster Energy C.Z.: a single short stroke in the Mesh Panel 'no collected' box, read as 1 mesh panel (it may be a stray mark - the compound's own collection is 28571). Nothing else written. No hire agreement number; no comments. Both signatures dated 22/10/26 (the own
D29: Totals | E29: =SUM(E4:E28) -> 476 | F29: =SUM(F4:F28) -> 491 | G29: =SUM(G4:G28) -> 474 | H29: =SUM(H4:H28) -> 5 | I29: =SUM(I4:I28) -> 19 | J29: =SUM(J4:J28) -> 45 | K29: =SUM(K4:K28) -> 35 | L29: =SUM(L4:L28) -> 1
