Workbook
Name CUBE: Parameters!$B$1
Name East_List: Lists!$C$1:$C$10
Name ENTITY: Parameters!$B$2
Name MEASURE: Parameters!$B$3
Name Month: Parameters!$B$9
Name MONTH_CURRENT: Parameters!$C$9
Name MONTH_CURRENT_YTD: Parameters!$C$10
Name MONTH_LY: Parameters!$D$9
Name MONTH_LY_YTD: Parameters!$D$10
Name North_List: Lists!$E$1:$E$6
Name South_List: Lists!$G$1:$G$9
Name West_List: Lists!$I$1:$I$9
Name YEAR: Parameters!$B$10

Sheet Cognos_Office_Connection_Cache

Sheet Parameters
A1: CUBE: | B1: Coates:General Ledger | J1: CY | K1: PY
A2: Financial Entity | B2: All Financial Entities | I2: Jul | J2: 2026-07 | K2: 2025-07
A3: Plan Measure | B3: Total | I3: Aug | J3: 2026-08 | K3: 2025-08
I4: Sep | J4: 2026-09 | K4: 2025-09
A5: Actual | B5: Actual | I5: Oct | J5: 2026-10 | K5: 2025-10
A6: Budget | B6: Target Budget | I6: Nov | J6: 2026-11 | K6: 2025-11
A7: Forecast | B7: Forecast Current | I7: Dec | J7: 2026-12 | K7: 2025-12
I8: Jan | J8: 2027-01 | K8: 2026-01
A9: Month | B9: Jul | C9: =+_xlfn.XLOOKUP($B9,$I$1:$I$13,J1:J13) -> 2026-07 | D9: =+_xlfn.XLOOKUP($B9,$I$1:$I$13,K1:K13) -> 2025-07 | I9: Feb | J9: 2027-02 | K9: 2026-02
B10: 2026 | C10: =+CONCATENATE(MONTH_CURRENT&"-YTD") -> 2026-07-YTD | D10: =+CONCATENATE(MONTH_LY&"-YTD") -> 2025-07-YTD | I10: Mar | J10: 2027-03 | K10: 2026-03
I11: Apr | J11: 2027-04 | K11: 2026-04
I12: May | J12: 2027-05 | K12: 2026-05
I13: Jun | J13: 2027-06 | K13: 2026-06

Sheet Lists
A1: IS | C1: IS_EAST BU | E1: IS_NORTH BU | G1: IS_SOUTH BU | I1: IS_WEST BU
C2: EAIS | E2: NOIS | G2: STIS | I2: WAIS
C3: THOR | E3: PHOS | G3: ROXD | I3: BAWI
C4: ISNS | E4: GLST | I4: MURR
I5: ONSL

Sheet Summary P&L>>

Sheet Group
A1: CUBE: | C1: Coates:General Ledger
A2: Financial Entity | C2: All Financial Entities
A3: Plan Measure | C3: Total
D4: =+Parameters!$B$10 -> 2026 | E4: =+Parameters!$B$10 -> 2026 | G4: =+Parameters!$B$10 -> 2026 | I4: =+D4-1 -> 2025 | L4: =+D4 -> 2026 | M4: =+E4 -> 2026 | O4: =+G4 -> 2026 | Q4: =+I4 -> 2025
D5: =+Parameters!$B$9 -> Jul | E5: =+Parameters!$B$9 -> Jul | G5: =+Parameters!$B$9 -> Jul | I5: =+E5 -> Jul | L5: =CONCATENATE(D5," ","YTD") -> Jul YTD | M5: =CONCATENATE(E5," ","YTD") -> Jul YTD | O5: =CONCATENATE(G5," ","YTD") -> Jul YTD | Q5: =CONCATENATE(I5," ","YTD") -> Jul YTD
D6: =+Parameters!B5 -> Actual | E6: =+Parameters!$B$6 -> Target Budget | G6: =+Parameters!$B$7 -> Forecast Current | I6: =+D6 -> Actual | L6: =+D6 -> Actual | M6: =+E6 -> Target Budget | O6: =+G6 -> Forecast Current | Q6: =+I6 -> Actual
D7: =+Lists!A1 -> IS | E7: =+D7 -> IS | F7: =+E7 -> IS | G7: =+F7 -> IS | H7: =+G7 -> IS | I7: =+H7 -> IS | J7: =+I7 -> IS | K7: =+J7 -> IS | L7: =+K7 -> IS | ... R7: =+Q7 -> IS
C8: FINANCIAL YEAR 2027 | D8: Industrial Solutions
D10: =CONCATENATE($D$5," ","MTD") -> Jul MTD | L10: =CONCATENATE($D$5," ","YTD") -> Jul YTD
D11: Actual | E11: Budget | F11: Var Bud | G11: Forecast | H11: Var Forecast | I11: Last Year | J11: Var LY | L11: Actual | M11: Budget | N11: Var Bud | O11: Forecast | P11: Var Forecast | Q11: Last Year | R11: Var LY
A12: Hire Revenue | B12: -1 | C12: Hire Revenue | D12: 3120323.8 | E12: 3399847.6 | F12: =+D12-E12 -> -279523.78 | G12: 0 | H12: =+D12-G12 -> 3120323.8 | I12: 2968368.8 | J12: =+D12-I12 -> 151955.04 | L12: 3120323.8 | M12: 3399847.6 | N12: =+L12-M12 -> -279523.78 | O12: 0 | P12: =+L12-O12 -> 3120323.8 | Q12: 2968368.8 | R12: =+L12-Q12 -> 151955.04 | T12: =D12/E12-1 -> -0.082216561 | U12: =+D12/I12-1 -> 0.051191429 | W12: =L12/M12-1 -> -0.082216561 | X12: =+L12/Q12-1 -> 0.051191429
A13: Rehire Revenue | B13: -1 | C13: Rehire Revenue | D13: 1121356.1 | E13: 623122.95 | F13: =+D13-E13 -> 498233.17 | G13: 0 | H13: =+D13-G13 -> 1121356.1 | I13: 462803.51 | J13: =+D13-I13 -> 658552.61 | L13: 1121356.1 | M13: 623122.95 | N13: =+L13-M13 -> 498233.17 | O13: 0 | P13: =+L13-O13 -> 1121356.1 | Q13: 462803.51 | R13: =+L13-Q13 -> 658552.61 | T13: =D13/E13-1 -> 0.79957441 | U13: =+D13/I13-1 -> 1.4229637 | W13: =L13/M13-1 -> 0.79957441 | X13: =+L13/Q13-1 -> 1.4229637
A14: Transport | B14: -1 | C14: Transport Revenue | D14: 443313.52 | E14: 313906.81 | F14: =+D14-E14 -> 129406.71 | G14: 0 | H14: =+D14-G14 -> 443313.52 | I14: 220060.08 | J14: =+D14-I14 -> 223253.44 | L14: 443313.52 | M14: 313906.81 | N14: =+L14-M14 -> 129406.71 | O14: 0 | P14: =+L14-O14 -> 443313.52 | Q14: 220060.08 | R14: =+L14-Q14 -> 223253.44 | T14: =D14/E14-1 -> 0.41224564 | U14: =+D14/I14-1 -> 1.0145113 | W14: =L14/M14-1 -> 0.41224564 | X14: =+L14/Q14-1 -> 1.0145113
A15: Other Revenue. | B15: -1 | C15: Other Revenue | D15: 1006392.8 | E15: 1320339.2 | F15: =+D15-E15 -> -313946.4 | G15: 0 | H15: =+D15-G15 -> 1006392.8 | I15: 791985.29 | J15: =+D15-I15 -> 214407.49 | L15: 1006392.8 | M15: 1320339.2 | N15: =+L15-M15 -> -313946.4 | O15: 0 | P15: =+L15-O15 -> 1006392.8 | Q15: 791985.29 | R15: =+L15-Q15 -> 214407.49 | T15: =D15/E15-1 -> -0.23777708 | U15: =+D15/I15-1 -> 0.27072156 | W15: =L15/M15-1 -> -0.23777708 | X15: =+L15/Q15-1 -> 0.27072156
A16: Total Combined Revenue | B16: -1 | C16: Total Revenue | D16: 5691386.2 | E16: 5657216.5 | F16: =+D16-E16 -> 34169.709 | G16: 0 | H16: =+D16-G16 -> 5691386.2 | I16: 4443217.6 | J16: =+D16-I16 -> 1248168.6 | L16: 5691386.2 | M16: 5657216.5 | N16: =+L16-M16 -> 34169.709 | O16: 0 | P16: =+L16-O16 -> 5691386.2 | Q16: 4443217.6 | R16: =+L16-Q16 -> 1248168.6 | T16: =D16/E16-1 -> 0.0060400215 | U16: =+D16/I16-1 -> 0.28091547 | W16: =L16/M16-1 -> 0.0060400215 | X16: =+L16/Q16-1 -> 0.28091547
A17: Total Repairs & Maintenance | B17: 1 | C17: Total Repairs & Maint | D17: 833490.17 | E17: 654170.76 | F17: =+D17-E17 -> 179319.41 | G17: 0 | H17: =+D17-G17 -> 833490.17 | I17: 588110.85 | J17: =+D17-I17 -> 245379.32 | L17: 833490.17 | M17: 654170.76 | N17: =+L17-M17 -> 179319.41 | O17: 0 | P17: =+L17-O17 -> 833490.17 | Q17: 588110.85 | R17: =+L17-Q17 -> 245379.32 | T17: =D17/E17-1 -> 0.27411713 | U17: =+D17/I17-1 -> 0.41723311 | W17: =L17/M17-1 -> 0.27411713 | X17: =+L17/Q17-1 -> 0.41723311
A18: Transport Expenses (Stat) | B18: 1 | C18: Transport | D18: 418026.62 | E18: 274176.39 | F18: =+D18-E18 -> 143850.23 | G18: 0 | H18: =+D18-G18 -> 418026.62 | I18: 258588.78 | J18: =+D18-I18 -> 159437.84 | L18: 418026.62 | M18: 274176.39 | N18: =+L18-M18 -> 143850.23 | O18: 0 | P18: =+L18-O18 -> 418026.62 | Q18: 258588.78 | R18: =+L18-Q18 -> 159437.84 | T18: =D18/E18-1 -> 0.52466308 | U18: =+D18/I18-1 -> 0.61656906 | W18: =L18/M18-1 -> 0.52466308 | X18: =+L18/Q18-1 -> 0.61656906
A19: Rehire Expenses | B19: 1 | C19: Rehire | D19: 895682.45 | E19: 530001.7 | F19: =+D19-E19 -> 365680.75 | G19: 0 | H19: =+D19-G19 -> 895682.45 | I19: 418146.33 | J19: =+D19-I19 -> 477536.12 | L19: 895682.45 | M19: 530001.7 | N19: =+L19-M19 -> 365680.75 | O19: 0 | P19: =+L19-O19 -> 895682.45 | Q19: 418146.33 | R19: =+L19-Q19 -> 477536.12 | T19: =D19/E19-1 -> 0.68996148 | U19: =+D19/I19-1 -> 1.1420311 | W19: =L19/M19-1 -> 0.68996148 | X19: =+L19/Q19-1 -> 1.1420311
A20: Profit/Loss on Sale of Asset | B20: 1 | C20: POSA | D20: 0 | E20: 0 | F20: =+D20-E20 -> 0 | G20: 0 | H20: =+D20-G20 -> 0 | I20: 0 | J20: =+D20-I20 -> 0 | L20: 0 | M20: 0 | N20: =+L20-M20 -> 0 | O20: 0 | P20: =+L20-O20 -> 0 | Q20: 0 | R20: =+L20-Q20 -> 0
A21: Other Direct Costs | B21: 1 | C21: Other Direct Costs | D21: 837430.39 | E21: 1106545.2 | F21: =+D21-E21 -> -269114.8 | G21: 0 | H21: =+D21-G21 -> 837430.39 | I21: 682634.77 | J21: =+D21-I21 -> 154795.62 | L21: 837430.39 | M21: 1106545.2 | N21: =+L21-M21 -> -269114.8 | O21: 0 | P21: =+L21-O21 -> 837430.39 | Q21: 682634.77 | R21: =+L21-Q21 -> 154795.62 | T21: =D21/E21-1 -> -0.24320272 | U21: =+D21/I21-1 -> 0.22676199 | W21: =L21/M21-1 -> -0.24320272 | X21: =+L21/Q21-1 -> 0.22676199
A22: Total Combined Direct Costs (Stat) | B22: 1 | C22: Total Direct Costs | D22: 2984629.6 | E22: 2564894 | F22: =+D22-E22 -> 419735.6 | G22: 0 | H22: =+D22-G22 -> 2984629.6 | I22: 1947480.7 | J22: =+D22-I22 -> 1037148.9 | L22: 2984629.6 | M22: 2564894 | N22: =+L22-M22 -> 419735.6 | O22: 0 | P22: =+L22-O22 -> 2984629.6 | Q22: 1947480.7 | R22: =+L22-Q22 -> 1037148.9 | T22: =D22/E22-1 -> 0.16364637 | U22: =+D22/I22-1 -> 0.53255926 | W22: =L22/M22-1 -> 0.16364637 | X22: =+L22/Q22-1 -> 0.53255926
A23: Gross Margin - Post Allocations (Stat) | B23: -1 | C23: Gross Margin | D23: 2706756.6 | E23: 3092322.5 | F23: =+D23-E23 -> -385565.89 | G23: 0 | H23: =+D23-G23 -> 2706756.6 | I23: 2495736.9 | J23: =+D23-I23 -> 211019.68 | L23: 2706756.6 | M23: 3092322.5 | N23: =+L23-M23 -> -385565.89 | O23: 0 | P23: =+L23-O23 -> 2706756.6 | Q23: 2495736.9 | R23: =+L23-Q23 -> 211019.68 | T23: =D23/E23-1 -> -0.12468489 | U23: =+D23/I23-1 -> 0.084552053 | W23: =L23/M23-1 -> -0.12468489 | X23: =+L23/Q23-1 -> 0.084552053
A24: Property (Stat) | B24: 1 | C24: Property | D24: 163404.8 | E24: 154645.62 | F24: =+D24-E24 -> 8759.1777 | G24: 0 | H24: =+D24-G24 -> 163404.8 | I24: 143745.34 | J24: =+D24-I24 -> 19659.46 | L24: 163404.8 | M24: 154645.62 | N24: =+L24-M24 -> 8759.1777 | O24: 0 | P24: =+L24-O24 -> 163404.8 | Q24: 143745.34 | R24: =+L24-Q24 -> 19659.46 | T24: =D24/E24-1 -> 0.056640321 | U24: =+D24/I24-1 -> 0.13676589 | W24: =L24/M24-1 -> 0.056640321 | X24: =+L24/Q24-1 -> 0.13676589
A25: Direct Staff Costs (Stat) | B25: 1 | C25: Direct Staff | D25: 321844.25 | E25: 378225.84 | F25: =+D25-E25 -> -56381.587 | G25: 0 | H25: =+D25-G25 -> 321844.25 | I25: 448435.18 | J25: =+D25-I25 -> -126590.93 | L25: 321844.25 | M25: 378225.84 | N25: =+L25-M25 -> -56381.587 | O25: 0 | P25: =+L25-O25 -> 321844.25 | Q25: 448435.18 | R25: =+L25-Q25 -> -126590.93 | T25: =D25/E25-1 -> -0.14906858 | U25: =+D25/I25-1 -> -0.28229482 | W25: =L25/M25-1 -> -0.14906858 | X25: =+L25/Q25-1 -> -0.28229482
A26: Indirect Staff Costs | B26: 1 | C26: Indirect Staff | D26: 13786.49 | E26: 14480.228 | F26: =+D26-E26 -> -693.73766 | G26: 0 | H26: =+D26-G26 -> 13786.49 | I26: 20678.24 | J26: =+D26-I26 -> -6891.75 | L26: 13786.49 | M26: 14480.228 | N26: =+L26-M26 -> -693.73766 | O26: 0 | P26: =+L26-O26 -> 13786.49 | Q26: 20678.24 | R26: =+L26-Q26 -> -6891.75 | T26: =D26/E26-1 -> -0.047909306 | U26: =+D26/I26-1 -> -0.33328513 | W26: =L26/M26-1 -> -0.047909306 | X26: =+L26/Q26-1 -> -0.33328513
A27: Marketing and Entertainment (BUFR) | B27: 1 | C27: Marketing/Entertainment | D27: 373.95 | E27: 432.30089 | F27: =+D27-E27 -> -58.35089 | G27: 0 | H27: =+D27-G27 -> 373.95 | I27: 15.68 | J27: =+D27-I27 -> 358.27 | L27: 373.95 | M27: 432.30089 | N27: =+L27-M27 -> -58.35089 | O27: 0 | P27: =+L27-O27 -> 373.95 | Q27: 15.68 | R27: =+L27-Q27 -> 358.27
A28: Telecommunications | B28: 1 | C28: Telecommunications | D28: 7791.84 | E28: 8308.4086 | F28: =+D28-E28 -> -516.56859 | G28: 0 | H28: =+D28-G28 -> 7791.84 | I28: 8969.2 | J28: =+D28-I28 -> -1177.36 | L28: 7791.84 | M28: 8308.4086 | N28: =+L28-M28 -> -516.56859 | O28: 0 | P28: =+L28-O28 -> 7791.84 | Q28: 8969.2 | R28: =+L28-Q28 -> -1177.36 | T28: =D28/E28-1 -> -0.062174192 | U28: =+D28/I28-1 -> -0.131267 | W28: =L28/M28-1 -> -0.062174192 | X28: =+L28/Q28-1 -> -0.131267
A29: IT & EDP Expenses | B29: 1 | C29: IT&EDP | D29: 9783.79 | E29: 4615.7283 | F29: =+D29-E29 -> 5168.0617 | G29: 0 | H29: =+D29-G29 -> 9783.79 | I29: 2663.06 | J29: =+D29-I29 -> 7120.73 | L29: 9783.79 | M29: 4615.7283 | N29: =+L29-M29 -> 5168.0617 | O29: 0 | P29: =+L29-O29 -> 9783.79 | Q29: 2663.06 | R29: =+L29-Q29 -> 7120.73 | T29: =D29/E29-1 -> 1.1196633 | U29: =+D29/I29-1 -> 2.6738902 | W29: =L29/M29-1 -> 1.1196633 | X29: =+L29/Q29-1 -> 2.6738902
A30: Travel & Accomodation Expense | B30: 1 | C30: Travel & Accommodation | D30: 22276.94 | E30: 13131.251 | F30: =+D30-E30 -> 9145.6889 | G30: 0 | H30: =+D30-G30 -> 22276.94 | I30: 18769.05 | J30: =+D30-I30 -> 3507.89 | L30: 22276.94 | M30: 13131.251 | N30: =+L30-M30 -> 9145.6889 | O30: 0 | P30: =+L30-O30 -> 22276.94 | Q30: 18769.05 | R30: =+L30-Q30 -> 3507.89 | T30: =D30/E30-1 -> 0.69648268 | U30: =+D30/I30-1 -> 0.18689758 | W30: =L30/M30-1 -> 0.69648268 | X30: =+L30/Q30-1 -> 0.18689758
A31: Bad Debts | B31: 1 | C31: Bad Debts | D31: 9930.72 | E31: 9490.7509 | F31: =+D31-E31 -> 439.96907 | G31: 0 | H31: =+D31-G31 -> 9930.72 | I31: 7642.54 | J31: =+D31-I31 -> 2288.18 | L31: 9930.72 | M31: 9490.7509 | N31: =+L31-M31 -> 439.96907 | O31: 0 | P31: =+L31-O31 -> 9930.72 | Q31: 7642.54 | R31: =+L31-Q31 -> 2288.18 | T31: =D31/E31-1 -> 0.046357667 | U31: =+D31/I31-1 -> 0.29940046 | W31: =L31/M31-1 -> 0.046357667 | X31: =+L31/Q31-1 -> 0.29940046
A32: Branch Admin (Stat) | B32: 1 | C32: Total Branch Administration | D32: 25778.56 | E32: 24575.884 | F32: =+D32-E32 -> 1202.6757 | G32: 0 | H32: =+D32-G32 -> 25778.56 | I32: 40999.6 | J32: =+D32-I32 -> -15221.04 | L32: 25778.56 | M32: 24575.884 | N32: =+L32-M32 -> 1202.6757 | O32: 0 | P32: =+L32-O32 -> 25778.56 | Q32: 40999.6 | R32: =+L32-Q32 -> -15221.04 | T32: =D32/E32-1 -> 0.048937231 | U32: =+D32/I32-1 -> -0.3712485 | W32: =L32/M32-1 -> 0.048937231 | X32: =+L32/Q32-1 -> -0.3712485
A33: Statutory Cost | B33: 1 | C33: Statutory | D33: 5470.64 | E33: 5474.1733 | F33: =+D33-E33 -> -3.5332598 | G33: 0 | H33: =+D33-G33 -> 5470.64 | I33: 5321.53 | J33: =+D33-I33 -> 149.11 | L33: 5470.64 | M33: 5474.1733 | N33: =+L33-M33 -> -3.5332598 | O33: 0 | P33: =+L33-O33 -> 5470.64 | Q33: 5321.53 | R33: =+L33-Q33 -> 149.11 | T33: =D33/E33-1 -> -0.00064544171 | U33: =+D33/I33-1 -> 0.028020137 | W33: =L33/M33-1 -> -0.00064544171 | X33: =+L33/Q33-1 -> 0.028020137
A34: Shared services & Allocated Costs | B34: 1 | C34: Shared services & Allocated Costs | D34: 726668.08 | E34: 711838.57 | F34: =+D34-E34 -> 14829.507 | G34: 0 | H34: =+D34-G34 -> 726668.08 | I34: 679637.45 | J34: =+D34-I34 -> 47030.63 | L34: 726668.08 | M34: 711838.57 | N34: =+L34-M34 -> 14829.507 | O34: 0 | P34: =+L34-O34 -> 726668.08 | Q34: 679637.45 | R34: =+L34-Q34 -> 47030.63 | T34: =D34/E34-1 -> 0.020832683 | U34: =+D34/I34-1 -> 0.069199586 | W34: =L34/M34-1 -> 0.020832683 | X34: =+L34/Q34-1 -> 0.069199586
A35: Total Combined Overheads (Stat) | B35: 1 | C35: Total Overheads | D35: 1307110.1 | E35: 1325218.8 | F35: =+D35-E35 -> -18108.698 | G35: 0 | H35: =+D35-G35 -> 1307110.1 | I35: 1376876.9 | J35: =+D35-I35 -> -69766.81 | L35: 1307110.1 | M35: 1325218.8 | N35: =+L35-M35 -> -18108.698 | O35: 0 | P35: =+L35-O35 -> 1307110.1 | Q35: 1376876.9 | R35: =+L35-Q35 -> -69766.81 | T35: =D35/E35-1 -> -0.013664686 | U35: =+D35/I35-1 -> -0.050670333 | W35: =L35/M35-1 -> -0.013664686 | X35: =+L35/Q35-1 -> -0.050670333
A36: EBITDA - Post Allocations (Stat) | B36: -1 | C36: EBITDA | D36: 1399646.5 | E36: 1767103.7 | F36: =+D36-E36 -> -367457.19 | G36: 0 | H36: =+D36-G36 -> 1399646.5 | I36: 1118860 | J36: =+D36-I36 -> 280786.49 | L36: 1399646.5 | M36: 1767103.7 | N36: =+L36-M36 -> -367457.19 | O36: 0 | P36: =+L36-O36 -> 1399646.5 | Q36: 1118860 | R36: =+L36-Q36 -> 280786.49 | T36: =D36/E36-1 -> -0.20794319 | U36: =+D36/I36-1 -> 0.25095765 | W36: =L36/M36-1 -> -0.20794319 | X36: =+L36/Q36-1 -> 0.25095765
A37: Total Combined Depreciation (Stat) | B37: 1 | C37: Depreciation | D37: 688818.24 | E37: 728249.92 | F37: =+D37-E37 -> -39431.678 | G37: 0 | H37: =+D37-G37 -> 688818.24 | I37: 667543.06 | J37: =+D37-I37 -> 21275.18 | L37: 688818.24 | M37: 728249.92 | N37: =+L37-M37 -> -39431.678 | O37: 0 | P37: =+L37-O37 -> 688818.24 | Q37: 667543.06 | R37: =+L37-Q37 -> 21275.18 | T37: =D37/E37-1 -> -0.054145804 | U37: =+D37/I37-1 -> 0.031870873 | W37: =L37/M37-1 -> -0.054145804 | X37: =+L37/Q37-1 -> 0.031870873
A38: EBIT - Post Allocations (Stat) | B38: -1 | C38: EBIT | D38: 710828.29 | E38: 1038853.8 | F38: =+D38-E38 -> -328025.51 | G38: 0 | H38: =+D38-G38 -> 710828.29 | I38: 451316.98 | J38: =+D38-I38 -> 259511.31 | L38: 710828.29 | M38: 1038853.8 | N38: =+L38-M38 -> -328025.51 | O38: 0 | P38: =+L38-O38 -> 710828.29 | Q38: 451316.98 | R38: =+L38-Q38 -> 259511.31 | T38: =D38/E38-1 -> -0.31575715 | U38: =+D38/I38-1 -> 0.57500897 | W38: =L38/M38-1 -> -0.31575715 | X38: =+L38/Q38-1 -> 0.57500897
P39: =+L39-O39 -> 0
B40: 1 | C40: Profit and Loss KPI Ratios | P40: =+L40-O40 -> 0
A41: Rehire Recovery % | B41: 1 | C41: Rehire Recovery | D41: 1.2519572 | E41: 1.1756999 | F41: =+D41-E41 -> 0.076257311 | G41: 0 | H41: =+D41-G41 -> 1.2519572 | I41: 1.106798 | J41: =+D41-I41 -> 0.14515926 | L41: 1.2519572 | M41: 1.1756999 | N41: =+L41-M41 -> 0.076257311 | O41: 0 | P41: =+L41-O41 -> 1.2519572 | Q41: 1.106798 | R41: =+L41-Q41 -> 0.14515926
...

Sheet East
A1: CUBE: | C1: Coates:General Ledger
A2: Financial Entity | C2: All Financial Entities
A3: Plan Measure | C3: Total
D4: =+Parameters!$B$10 -> 2026 | E4: =+Parameters!$B$10 -> 2026 | G4: =+Parameters!$B$10 -> 2026 | I4: =+D4-1 -> 2025 | L4: =+D4 -> 2026 | M4: =+E4 -> 2026 | O4: =+G4 -> 2026 | Q4: =+I4 -> 2025
D5: =+Parameters!$B$9 -> Jul | E5: =+Parameters!$B$9 -> Jul | G5: =+Parameters!$B$9 -> Jul | I5: =+E5 -> Jul | L5: =CONCATENATE(D5," ","YTD") -> Jul YTD | M5: =CONCATENATE(E5," ","YTD") -> Jul YTD | O5: =CONCATENATE(G5," ","YTD") -> Jul YTD | Q5: =CONCATENATE(I5," ","YTD") -> Jul YTD
D6: =+Parameters!B5 -> Actual | E6: =+Parameters!$B$6 -> Target Budget | G6: =+Parameters!$B$7 -> Forecast Current | I6: =+D6 -> Actual | L6: =+D6 -> Actual | M6: =+E6 -> Target Budget | O6: =+G6 -> Forecast Current | Q6: =+I6 -> Actual
D7: =+Lists!C1 -> IS_EAST BU | E7: =+D7 -> IS_EAST BU | F7: =+E7 -> IS_EAST BU | G7: =+F7 -> IS_EAST BU | H7: =+G7 -> IS_EAST BU | I7: =+H7 -> IS_EAST BU | J7: =+I7 -> IS_EAST BU | K7: =+J7 -> IS_EAST BU | L7: =+K7 -> IS_EAST BU | ... R7: =+Q7 -> IS_EAST BU
C8: =+Group!$C$8 -> FINANCIAL YEAR 2027 | D8: East - Industrial Solutions
D10: =CONCATENATE($D$5," ","MTD") -> Jul MTD | L10: =CONCATENATE($D$5," ","YTD") -> Jul YTD
D11: Actual | E11: Budget | F11: Var Bud | G11: Forecast | H11: Var Forecast | I11: Last Year | J11: Var LY | L11: Actual | M11: Budget | N11: Var Bud | O11: Forecast | P11: Var Forecast | Q11: Last Year | R11: Var LY
A12: Hire Revenue | B12: -1 | C12: Hire Revenue | D12: 295833.71 | E12: 342398.13 | F12: =+D12-E12 -> -46564.423 | G12: 0 | H12: =+D12-G12 -> 295833.71 | I12: 339897.2 | J12: =+D12-I12 -> -44063.49 | L12: 295833.71 | M12: 342398.13 | N12: =+L12-M12 -> -46564.423 | O12: 0 | P12: =+L12-O12 -> 295833.71 | Q12: 339897.2 | R12: =+L12-Q12 -> -44063.49
A13: Rehire Revenue | B13: -1 | C13: Rehire Revenue | D13: 31460.19 | E13: 58193.218 | F13: =+D13-E13 -> -26733.028 | G13: 0 | H13: =+D13-G13 -> 31460.19 | I13: 12448.17 | J13: =+D13-I13 -> 19012.02 | L13: 31460.19 | M13: 58193.218 | N13: =+L13-M13 -> -26733.028 | O13: 0 | P13: =+L13-O13 -> 31460.19 | Q13: 12448.17 | R13: =+L13-Q13 -> 19012.02
A14: Transport | B14: -1 | C14: Transport Revenue | D14: 34016.74 | E14: 50418.684 | F14: =+D14-E14 -> -16401.944 | G14: 0 | H14: =+D14-G14 -> 34016.74 | I14: 37516.46 | J14: =+D14-I14 -> -3499.72 | L14: 34016.74 | M14: 50418.684 | N14: =+L14-M14 -> -16401.944 | O14: 0 | P14: =+L14-O14 -> 34016.74 | Q14: 37516.46 | R14: =+L14-Q14 -> -3499.72
A15: Other Revenue. | B15: -1 | C15: Other Revenue | D15: 39410.3 | E15: 84577.144 | F15: =+D15-E15 -> -45166.844 | G15: 0 | H15: =+D15-G15 -> 39410.3 | I15: 53735.05 | J15: =+D15-I15 -> -14324.75 | L15: 39410.3 | M15: 84577.144 | N15: =+L15-M15 -> -45166.844 | O15: 0 | P15: =+L15-O15 -> 39410.3 | Q15: 53735.05 | R15: =+L15-Q15 -> -14324.75
A16: Total Combined Revenue | B16: -1 | C16: Total Revenue | D16: 400720.94 | E16: 535587.18 | F16: =+D16-E16 -> -134866.24 | G16: 0 | H16: =+D16-G16 -> 400720.94 | I16: 443596.88 | J16: =+D16-I16 -> -42875.94 | L16: 400720.94 | M16: 535587.18 | N16: =+L16-M16 -> -134866.24 | O16: 0 | P16: =+L16-O16 -> 400720.94 | Q16: 443596.88 | R16: =+L16-Q16 -> -42875.94 | T16: =D16/E16 -> 0.74818994
A17: Total Repairs & Maintenance | B17: 1 | C17: Total Repairs & Maint | D17: 83582.93 | E17: 62304.963 | F17: =+D17-E17 -> 21277.967 | G17: 0 | H17: =+D17-G17 -> 83582.93 | I17: 71650.28 | J17: =+D17-I17 -> 11932.65 | L17: 83582.93 | M17: 62304.963 | N17: =+L17-M17 -> 21277.967 | O17: 0 | P17: =+L17-O17 -> 83582.93 | Q17: 71650.28 | R17: =+L17-Q17 -> 11932.65
A18: Transport Expenses (Stat) | B18: 1 | C18: Transport | D18: 32645.06 | E18: 46646.407 | F18: =+D18-E18 -> -14001.347 | G18: 0 | H18: =+D18-G18 -> 32645.06 | I18: 58320.71 | J18: =+D18-I18 -> -25675.65 | L18: 32645.06 | M18: 46646.407 | N18: =+L18-M18 -> -14001.347 | O18: 0 | P18: =+L18-O18 -> 32645.06 | Q18: 58320.71 | R18: =+L18-Q18 -> -25675.65
A19: Rehire Expenses | B19: 1 | C19: Rehire | D19: 32658.08 | E19: 45111.022 | F19: =+D19-E19 -> -12452.942 | G19: 0 | H19: =+D19-G19 -> 32658.08 | I19: 14507.84 | J19: =+D19-I19 -> 18150.24 | L19: 32658.08 | M19: 45111.022 | N19: =+L19-M19 -> -12452.942 | O19: 0 | P19: =+L19-O19 -> 32658.08 | Q19: 14507.84 | R19: =+L19-Q19 -> 18150.24
A20: Profit/Loss on Sale of Asset | B20: 1 | C20: POSA | D20: 0 | E20: 0 | F20: =+D20-E20 -> 0 | G20: 0 | H20: =+D20-G20 -> 0 | I20: 0 | J20: =+D20-I20 -> 0 | L20: 0 | M20: 0 | N20: =+L20-M20 -> 0 | O20: 0 | P20: =+L20-O20 -> 0 | Q20: 0 | R20: =+L20-Q20 -> 0
A21: Other Direct Costs | B21: 1 | C21: Other Direct Costs | D21: 39481.51 | E21: 73474.596 | F21: =+D21-E21 -> -33993.086 | G21: 0 | H21: =+D21-G21 -> 39481.51 | I21: 11277.17 | J21: =+D21-I21 -> 28204.34 | L21: 39481.51 | M21: 73474.596 | N21: =+L21-M21 -> -33993.086 | O21: 0 | P21: =+L21-O21 -> 39481.51 | Q21: 11277.17 | R21: =+L21-Q21 -> 28204.34
A22: Total Combined Direct Costs (Stat) | B22: 1 | C22: Total Direct Costs | D22: 188367.58 | E22: 227536.99 | F22: =+D22-E22 -> -39169.408 | G22: 0 | H22: =+D22-G22 -> 188367.58 | I22: 155756 | J22: =+D22-I22 -> 32611.58 | L22: 188367.58 | M22: 227536.99 | N22: =+L22-M22 -> -39169.408 | O22: 0 | P22: =+L22-O22 -> 188367.58 | Q22: 155756 | R22: =+L22-Q22 -> 32611.58 | T22: =D22/E22 -> 0.82785477
A23: Gross Margin - Post Allocations (Stat) | B23: -1 | C23: Gross Margin | D23: 212353.36 | E23: 308050.19 | F23: =+D23-E23 -> -95696.83 | G23: 0 | H23: =+D23-G23 -> 212353.36 | I23: 287840.88 | J23: =+D23-I23 -> -75487.52 | L23: 212353.36 | M23: 308050.19 | N23: =+L23-M23 -> -95696.83 | O23: 0 | P23: =+L23-O23 -> 212353.36 | Q23: 287840.88 | R23: =+L23-Q23 -> -75487.52 | T23: =+D23/D16 -> 0.52992828 | U23: =+E23/E16 -> 0.57516349
A24: Property (Stat) | B24: 1 | C24: Property | D24: 35543.75 | E24: 37815.408 | F24: =+D24-E24 -> -2271.6578 | G24: 0 | H24: =+D24-G24 -> 35543.75 | I24: 36236.91 | J24: =+D24-I24 -> -693.16 | L24: 35543.75 | M24: 37815.408 | N24: =+L24-M24 -> -2271.6578 | O24: 0 | P24: =+L24-O24 -> 35543.75 | Q24: 36236.91 | R24: =+L24-Q24 -> -693.16
A25: Direct Staff Costs (Stat) | B25: 1 | C25: Direct Staff | D25: 33231.13 | E25: 39888.072 | F25: =+D25-E25 -> -6656.9425 | G25: 0 | H25: =+D25-G25 -> 33231.13 | I25: 69902.57 | J25: =+D25-I25 -> -36671.44 | L25: 33231.13 | M25: 39888.072 | N25: =+L25-M25 -> -6656.9425 | O25: 0 | P25: =+L25-O25 -> 33231.13 | Q25: 69902.57 | R25: =+L25-Q25 -> -36671.44
A26: Indirect Staff Costs | B26: 1 | C26: Indirect Staff | D26: 209.85 | E26: 757.81347 | F26: =+D26-E26 -> -547.96347 | G26: 0 | H26: =+D26-G26 -> 209.85 | I26: 171.66 | J26: =+D26-I26 -> 38.19 | L26: 209.85 | M26: 757.81347 | N26: =+L26-M26 -> -547.96347 | O26: 0 | P26: =+L26-O26 -> 209.85 | Q26: 171.66 | R26: =+L26-Q26 -> 38.19
A27: Marketing and Entertainment (BUFR) | B27: 1 | C27: Marketing/Entertainment | D27: 0 | E27: 105.42672 | F27: =+D27-E27 -> -105.42672 | G27: 0 | H27: =+D27-G27 -> 0 | I27: 0 | J27: =+D27-I27 -> 0 | L27: 0 | M27: 105.42672 | N27: =+L27-M27 -> -105.42672 | O27: 0 | P27: =+L27-O27 -> 0 | Q27: 0 | R27: =+L27-Q27 -> 0
A28: Telecommunications | B28: 1 | C28: Telecommunications | D28: 1134.39 | E28: 1352.1444 | F28: =+D28-E28 -> -217.75442 | G28: 0 | H28: =+D28-G28 -> 1134.39 | I28: 1208.34 | J28: =+D28-I28 -> -73.95 | L28: 1134.39 | M28: 1352.1444 | N28: =+L28-M28 -> -217.75442 | O28: 0 | P28: =+L28-O28 -> 1134.39 | Q28: 1208.34 | R28: =+L28-Q28 -> -73.95
A29: IT & EDP Expenses | B29: 1 | C29: IT&EDP | D29: 1484 | E29: 1305.6466 | F29: =+D29-E29 -> 178.35338 | G29: 0 | H29: =+D29-G29 -> 1484 | I29: 918.9 | J29: =+D29-I29 -> 565.1 | L29: 1484 | M29: 1305.6466 | N29: =+L29-M29 -> 178.35338 | O29: 0 | P29: =+L29-O29 -> 1484 | Q29: 918.9 | R29: =+L29-Q29 -> 565.1
A30: Travel & Accomodation Expense | B30: 1 | C30: Travel & Accommodation | D30: 1174.08 | E30: 2315.6767 | F30: =+D30-E30 -> -1141.5967 | G30: 0 | H30: =+D30-G30 -> 1174.08 | I30: 10801.22 | J30: =+D30-I30 -> -9627.14 | L30: 1174.08 | M30: 2315.6767 | N30: =+L30-M30 -> -1141.5967 | O30: 0 | P30: =+L30-O30 -> 1174.08 | Q30: 10801.22 | R30: =+L30-Q30 -> -9627.14
A31: Bad Debts | B31: 1 | C31: Bad Debts | D31: 763.26 | E31: 1029.3034 | F31: =+D31-E31 -> -266.04343 | G31: 0 | H31: =+D31-G31 -> 763.26 | I31: 763.15 | J31: =+D31-I31 -> 0.11 | L31: 763.26 | M31: 1029.3034 | N31: =+L31-M31 -> -266.04343 | O31: 0 | P31: =+L31-O31 -> 763.26 | Q31: 763.15 | R31: =+L31-Q31 -> 0.11
A32: Branch Admin (Stat) | B32: 1 | C32: Total Branch Administration | D32: 6465.17 | E32: 6951.4279 | F32: =+D32-E32 -> -486.2579 | G32: 0 | H32: =+D32-G32 -> 6465.17 | I32: 9261.28 | J32: =+D32-I32 -> -2796.11 | L32: 6465.17 | M32: 6951.4279 | N32: =+L32-M32 -> -486.2579 | O32: 0 | P32: =+L32-O32 -> 6465.17 | Q32: 9261.28 | R32: =+L32-Q32 -> -2796.11
A33: Statutory Cost | B33: 1 | C33: Statutory | D33: 801.03 | E33: 804.56839 | F33: =+D33-E33 -> -3.538393 | G33: 0 | H33: =+D33-G33 -> 801.03 | I33: 779.67 | J33: =+D33-I33 -> 21.36 | L33: 801.03 | M33: 804.56839 | N33: =+L33-M33 -> -3.538393 | O33: 0 | P33: =+L33-O33 -> 801.03 | Q33: 779.67 | R33: =+L33-Q33 -> 21.36
A34: Shared services & Allocated Costs | B34: 1 | C34: Shared services & Allocated Costs | D34: 68196.34 | E34: 66837.161 | F34: =+D34-E34 -> 1359.1786 | G34: 0 | H34: =+D34-G34 -> 68196.34 | I34: 55868.95 | J34: =+D34-I34 -> 12327.39 | L34: 68196.34 | M34: 66837.161 | N34: =+L34-M34 -> 1359.1786 | O34: 0 | P34: =+L34-O34 -> 68196.34 | Q34: 55868.95 | R34: =+L34-Q34 -> 12327.39
A35: Total Combined Overheads (Stat) | B35: 1 | C35: Total Overheads | D35: 149003 | E35: 159162.65 | F35: =+D35-E35 -> -10159.649 | G35: 0 | H35: =+D35-G35 -> 149003 | I35: 185912.65 | J35: =+D35-I35 -> -36909.65 | L35: 149003 | M35: 159162.65 | N35: =+L35-M35 -> -10159.649 | O35: 0 | P35: =+L35-O35 -> 149003 | Q35: 185912.65 | R35: =+L35-Q35 -> -36909.65
... A38: EBIT - Post Allocations (Stat) | B38: -1 | C38: EBIT | D38: 36854.15 | E38: 107357.54 | F38: =+D38-E38 -> -70503.393 | G38: 0 | H38: =+D38-G38 -> 36854.15 | I38: 69382.65 | J38: =+D38-I38 -> -32528.5 | L38: 36854.15 | M38: 107357.54 | N38: =+L38-M38 -> -70503.393 | O38: 0 | P38: =+L38-O38 -> 36854.15 | Q38: 69382.65 | R38: =+L38-Q38 -> -32528.5
P39: =+L39-O39 -> 0
B40: 1 | C40: Profit and Loss KPI Ratios | P40: =+L40-O40 -> 0
A41: Rehire Recovery % | B41: 1 | C41: Rehire Recovery | D41: 0.96332026 | E41: 1.29 | F41: =+D41-E41 -> -0.32667974 | G41: 0 | H41: =+D41-G41 -> 0.96332026 | I41: 0.85803055 | J41: =+D41-I41 -> 0.1052897 | L41: 0.96332026 | M41: 1.29 | N41: =+L41-M41 -> -0.32667974 | O41: 0 | P41: =+L41-O41 -> 0.96332026 | Q41: 0.85803055 | R41: =+L41-Q41 -> 0.1052897
A42: Transport Recovery % | B42: 1 | C42: Transport Recovery | D42: 1.042018 | E42: 1.0808696 | F42: =+D42-E42 -> -0.038851604 | G42: 0 | H42: =+D42-G42 -> 1.042018 | I42: 0.64327852 | J42: =+D42-I42 -> 0.39873948 | L42: 1.042018 | M42: 1.0808696 | N42: =+L42-M42 -> -0.038851604 | O42: 0 | P42: =+L42-O42 -> 1.042018 | Q42: 0.64327852 | R42: =+L42-Q42 -> 0.39873948
A43: Installation Recovery% | B43: 1 | C43: Labour Recovery - Installation | D43: 0 | E43: 1.28 | F43: =+D43-E43 -> -1.28 | G43: 0 | H43: =+D43-G43 -> 0 | I43: -15.157559 | J43: =+D43-I43 -> 15.157559 | L43: 0 | M43: 1.28 | N43: =+L43-M43 -> -1.28 | O43: 0 | P43: =+L43-O43 -> 0 | Q43: -15.157559 | R43: =+L43-Q43 -> 15.157559
...

Sheet North
A1: CUBE: | C1: Coates:General Ledger | E1: Target Budget FY25 Copy
A2: Financial Entity | C2: All Financial Entities
A3: Plan Measure | C3: Total
D4: =+Parameters!$B$10 -> 2026 | E4: =+Parameters!$B$10 -> 2026 | G4: =+Parameters!$B$10 -> 2026 | I4: =+D4-1 -> 2025 | L4: =+D4 -> 2026 | M4: =+E4 -> 2026 | O4: =+G4 -> 2026 | Q4: =+I4 -> 2025
D5: =+Parameters!$B$9 -> Jul | E5: =+Parameters!$B$9 -> Jul | G5: =+Parameters!$B$9 -> Jul | I5: =+E5 -> Jul | L5: =CONCATENATE(D5," ","YTD") -> Jul YTD | M5: =CONCATENATE(E5," ","YTD") -> Jul YTD | O5: =CONCATENATE(G5," ","YTD") -> Jul YTD | Q5: =CONCATENATE(I5," ","YTD") -> Jul YTD
D6: =+Parameters!B5 -> Actual | E6: =+Parameters!$B$6 -> Target Budget | G6: =+Parameters!$B$7 -> Forecast Current | I6: =+D6 -> Actual | L6: =+D6 -> Actual | M6: =+E6 -> Target Budget | O6: =+G6 -> Forecast Current | Q6: =+I6 -> Actual
D7: =+Lists!E1 -> IS_NORTH BU | E7: =+D7 -> IS_NORTH BU | F7: =+E7 -> IS_NORTH BU | G7: =+F7 -> IS_NORTH BU | H7: =+G7 -> IS_NORTH BU | I7: =+H7 -> IS_NORTH BU | J7: =+I7 -> IS_NORTH BU | K7: =+J7 -> IS_NORTH BU | L7: =+K7 -> IS_NORTH BU | ... R7: =+Q7 -> IS_NORTH BU
C8: =+Group!$C$8 -> FINANCIAL YEAR 2027 | D8: North - Industrial Solutions
D10: =CONCATENATE($D$5," ","MTD") -> Jul MTD | L10: =CONCATENATE($D$5," ","YTD") -> Jul YTD
D11: Actual | E11: Budget | F11: Var Bud | G11: Forecast | H11: Var Forecast | I11: Last Year | J11: Var LY | L11: Actual | M11: Budget | N11: Var Bud | O11: Forecast | P11: Var Forecast | Q11: Last Year | R11: Var LY
A12: Hire Revenue | B12: -1 | C12: Hire Revenue | D12: 792502.63 | E12: 760493.98 | F12: =+D12-E12 -> 32008.65 | G12: 0 | H12: =+D12-G12 -> 792502.63 | I12: 703471.47 | J12: =+D12-I12 -> 89031.16 | L12: 792502.63 | M12: 760493.98 | N12: =+L12-M12 -> 32008.65 | O12: 0 | P12: =+L12-O12 -> 792502.63 | Q12: 703471.47 | R12: =+L12-Q12 -> 89031.16
A13: Rehire Revenue | B13: -1 | C13: Rehire Revenue | D13: 164876.21 | E13: 122944.81 | F13: =+D13-E13 -> 41931.4 | G13: 0 | H13: =+D13-G13 -> 164876.21 | I13: 97045.5 | J13: =+D13-I13 -> 67830.71 | L13: 164876.21 | M13: 122944.81 | N13: =+L13-M13 -> 41931.4 | O13: 0 | P13: =+L13-O13 -> 164876.21 | Q13: 97045.5 | R13: =+L13-Q13 -> 67830.71
A14: Transport | B14: -1 | C14: Transport Revenue | D14: 196906.03 | E14: 103310.2 | F14: =+D14-E14 -> 93595.829 | G14: 0 | H14: =+D14-G14 -> 196906.03 | I14: 63096.01 | J14: =+D14-I14 -> 133810.02 | L14: 196906.03 | M14: 103310.2 | N14: =+L14-M14 -> 93595.829 | O14: 0 | P14: =+L14-O14 -> 196906.03 | Q14: 63096.01 | R14: =+L14-Q14 -> 133810.02
A15: Other Revenue. | B15: -1 | C15: Other Revenue | D15: 225330.46 | E15: 173074.34 | F15: =+D15-E15 -> 52256.119 | G15: 0 | H15: =+D15-G15 -> 225330.46 | I15: 53841.59 | J15: =+D15-I15 -> 171488.87 | L15: 225330.46 | M15: 173074.34 | N15: =+L15-M15 -> 52256.119 | O15: 0 | P15: =+L15-O15 -> 225330.46 | Q15: 53841.59 | R15: =+L15-Q15 -> 171488.87
A16: Total Combined Revenue | B16: -1 | C16: Total Revenue | D16: 1379615.3 | E16: 1159823.3 | F16: =+D16-E16 -> 219792 | G16: 0 | H16: =+D16-G16 -> 1379615.3 | I16: 917454.57 | J16: =+D16-I16 -> 462160.76 | L16: 1379615.3 | M16: 1159823.3 | N16: =+L16-M16 -> 219792 | O16: 0 | P16: =+L16-O16 -> 1379615.3 | Q16: 917454.57 | R16: =+L16-Q16 -> 462160.76 | T16: =D16/E16 -> 1.1895047
A17: Total Repairs & Maintenance | B17: 1 | C17: Total Repairs & Maint | D17: 188830.04 | E17: 149365.18 | F17: =+D17-E17 -> 39464.864 | G17: 0 | H17: =+D17-G17 -> 188830.04 | I17: 94879.4 | J17: =+D17-I17 -> 93950.64 | L17: 188830.04 | M17: 149365.18 | N17: =+L17-M17 -> 39464.864 | O17: 0 | P17: =+L17-O17 -> 188830.04 | Q17: 94879.4 | R17: =+L17-Q17 -> 93950.64
A18: Transport Expenses (Stat) | B18: 1 | C18: Transport | D18: 177517.12 | E18: 90478.882 | F18: =+D18-E18 -> 87038.238 | G18: 0 | H18: =+D18-G18 -> 177517.12 | I18: 64857.77 | J18: =+D18-I18 -> 112659.35 | L18: 177517.12 | M18: 90478.882 | N18: =+L18-M18 -> 87038.238 | O18: 0 | P18: =+L18-O18 -> 177517.12 | Q18: 64857.77 | R18: =+L18-Q18 -> 112659.35
A19: Rehire Expenses | B19: 1 | C19: Rehire | D19: 140650.11 | E19: 94688.155 | F19: =+D19-E19 -> 45961.955 | G19: 0 | H19: =+D19-G19 -> 140650.11 | I19: 80821.96 | J19: =+D19-I19 -> 59828.15 | L19: 140650.11 | M19: 94688.155 | N19: =+L19-M19 -> 45961.955 | O19: 0 | P19: =+L19-O19 -> 140650.11 | Q19: 80821.96 | R19: =+L19-Q19 -> 59828.15
A20: Profit/Loss on Sale of Asset | B20: 1 | C20: POSA | D20: 0 | E20: 0 | F20: =+D20-E20 -> 0 | G20: 0 | H20: =+D20-G20 -> 0 | I20: 0 | J20: =+D20-I20 -> 0 | L20: 0 | M20: 0 | N20: =+L20-M20 -> 0 | O20: 0 | P20: =+L20-O20 -> 0 | Q20: 0 | R20: =+L20-Q20 -> 0
A21: Other Direct Costs | B21: 1 | C21: Other Direct Costs | D21: 140188.56 | E21: 121628.99 | F21: =+D21-E21 -> 18559.574 | G21: 0 | H21: =+D21-G21 -> 140188.56 | I21: 35148.25 | J21: =+D21-I21 -> 105040.31 | L21: 140188.56 | M21: 121628.99 | N21: =+L21-M21 -> 18559.574 | O21: 0 | P21: =+L21-O21 -> 140188.56 | Q21: 35148.25 | R21: =+L21-Q21 -> 105040.31
A22: Total Combined Direct Costs (Stat) | B22: 1 | C22: Total Direct Costs | D22: 647185.83 | E22: 456161.2 | F22: =+D22-E22 -> 191024.63 | G22: 0 | H22: =+D22-G22 -> 647185.83 | I22: 275707.38 | J22: =+D22-I22 -> 371478.45 | L22: 647185.83 | M22: 456161.2 | N22: =+L22-M22 -> 191024.63 | O22: 0 | P22: =+L22-O22 -> 647185.83 | Q22: 275707.38 | R22: =+L22-Q22 -> 371478.45 | T22: =D22/E22 -> 1.4187656
A23: Gross Margin - Post Allocations (Stat) | B23: -1 | C23: Gross Margin | D23: 732429.5 | E23: 703662.13 | F23: =+D23-E23 -> 28767.366 | G23: 0 | H23: =+D23-G23 -> 732429.5 | I23: 641747.19 | J23: =+D23-I23 -> 90682.31 | L23: 732429.5 | M23: 703662.13 | N23: =+L23-M23 -> 28767.366 | O23: 0 | P23: =+L23-O23 -> 732429.5 | Q23: 641747.19 | R23: =+L23-Q23 -> 90682.31 | T23: =+D23/D16 -> 0.530894 | U23: =+E23/E16 -> 0.60669769
A24: Property (Stat) | B24: 1 | C24: Property | D24: 41248.3 | E24: 44024.154 | F24: =+D24-E24 -> -2775.8537 | G24: 0 | H24: =+D24-G24 -> 41248.3 | I24: 46354.06 | J24: =+D24-I24 -> -5105.76 | L24: 41248.3 | M24: 44024.154 | N24: =+L24-M24 -> -2775.8537 | O24: 0 | P24: =+L24-O24 -> 41248.3 | Q24: 46354.06 | R24: =+L24-Q24 -> -5105.76
A25: Direct Staff Costs (Stat) | B25: 1 | C25: Direct Staff | D25: 51117.11 | E25: 88411.927 | F25: =+D25-E25 -> -37294.817 | G25: 0 | H25: =+D25-G25 -> 51117.11 | I25: 121188.54 | J25: =+D25-I25 -> -70071.43 | L25: 51117.11 | M25: 88411.927 | N25: =+L25-M25 -> -37294.817 | O25: 0 | P25: =+L25-O25 -> 51117.11 | Q25: 121188.54 | R25: =+L25-Q25 -> -70071.43
A26: Indirect Staff Costs | B26: 1 | C26: Indirect Staff | D26: 728.44 | E26: 747.70002 | F26: =+D26-E26 -> -19.260023 | G26: 0 | H26: =+D26-G26 -> 728.44 | I26: 82.56 | J26: =+D26-I26 -> 645.88 | L26: 728.44 | M26: 747.70002 | N26: =+L26-M26 -> -19.260023 | O26: 0 | P26: =+L26-O26 -> 728.44 | Q26: 82.56 | R26: =+L26-Q26 -> 645.88
A27: Marketing and Entertainment (BUFR) | B27: 1 | C27: Marketing/Entertainment | D27: 373.95 | E27: 26.591667 | F27: =+D27-E27 -> 347.35833 | G27: 0 | H27: =+D27-G27 -> 373.95 | I27: 0 | J27: =+D27-I27 -> 373.95 | L27: 373.95 | M27: 26.591667 | N27: =+L27-M27 -> 347.35833 | O27: 0 | P27: =+L27-O27 -> 373.95 | Q27: 0 | R27: =+L27-Q27 -> 373.95
A28: Telecommunications | B28: 1 | C28: Telecommunications | D28: 1597.86 | E28: 1932.8658 | F28: =+D28-E28 -> -335.00583 | G28: 0 | H28: =+D28-G28 -> 1597.86 | I28: 2325.22 | J28: =+D28-I28 -> -727.36 | L28: 1597.86 | M28: 1932.8658 | N28: =+L28-M28 -> -335.00583 | O28: 0 | P28: =+L28-O28 -> 1597.86 | Q28: 2325.22 | R28: =+L28-Q28 -> -727.36
A29: IT & EDP Expenses | B29: 1 | C29: IT&EDP | D29: 5895.79 | E29: 1093.0708 | F29: =+D29-E29 -> 4802.7192 | G29: 0 | H29: =+D29-G29 -> 5895.79 | I29: -218.56 | J29: =+D29-I29 -> 6114.35 | L29: 5895.79 | M29: 1093.0708 | N29: =+L29-M29 -> 4802.7192 | O29: 0 | P29: =+L29-O29 -> 5895.79 | Q29: -218.56 | R29: =+L29-Q29 -> 6114.35
A30: Travel & Accomodation Expense | B30: 1 | C30: Travel & Accommodation | D30: 5979.85 | E30: 5373.8018 | F30: =+D30-E30 -> 606.04817 | G30: 0 | H30: =+D30-G30 -> 5979.85 | I30: 2801.89 | J30: =+D30-I30 -> 3177.96 | L30: 5979.85 | M30: 5373.8018 | N30: =+L30-M30 -> 606.04817 | O30: 0 | P30: =+L30-O30 -> 5979.85 | Q30: 2801.89 | R30: =+L30-Q30 -> 3177.96
A31: Bad Debts | B31: 1 | C31: Bad Debts | D31: 2277.73 | E31: 1949.4994 | F31: =+D31-E31 -> 328.2306 | G31: 0 | H31: =+D31-G31 -> 2277.73 | I31: 1578.37 | J31: =+D31-I31 -> 699.36 | L31: 2277.73 | M31: 1949.4994 | N31: =+L31-M31 -> 328.2306 | O31: 0 | P31: =+L31-O31 -> 2277.73 | Q31: 1578.37 | R31: =+L31-Q31 -> 699.36
A32: Branch Admin (Stat) | B32: 1 | C32: Total Branch Administration | D32: 4407.97 | E32: 4904.2078 | F32: =+D32-E32 -> -496.23782 | G32: 0 | H32: =+D32-G32 -> 4407.97 | I32: 9891.12 | J32: =+D32-I32 -> -5483.15 | L32: 4407.97 | M32: 4904.2078 | N32: =+L32-M32 -> -496.23782 | O32: 0 | P32: =+L32-O32 -> 4407.97 | Q32: 9891.12 | R32: =+L32-Q32 -> -5483.15
A33: Statutory Cost | B33: 1 | C33: Statutory | D33: 838.18 | E33: 838.1757 | F33: =+D33-E33 -> 0.0042999214 | G33: 0 | H33: =+D33-G33 -> 838.18 | I33: 784.32 | J33: =+D33-I33 -> 53.86 | L33: 838.18 | M33: 838.1757 | N33: =+L33-M33 -> 0.0042999214 | O33: 0 | P33: =+L33-O33 -> 838.18 | Q33: 784.32 | R33: =+L33-Q33 -> 53.86
A34: Shared services & Allocated Costs | B34: 1 | C34: Shared services & Allocated Costs | D34: 155023.5 | E34: 153400.22 | F34: =+D34-E34 -> 1623.2766 | G34: 0 | H34: =+D34-G34 -> 155023.5 | I34: 157691.59 | J34: =+D34-I34 -> -2668.09 | L34: 155023.5 | M34: 153400.22 | N34: =+L34-M34 -> 1623.2766 | O34: 0 | P34: =+L34-O34 -> 155023.5 | Q34: 157691.59 | R34: =+L34-Q34 -> -2668.09
A35: Total Combined Overheads (Stat) | B35: 1 | C35: Total Overheads | D35: 269488.68 | E35: 302702.22 | F35: =+D35-E35 -> -33213.537 | G35: 0 | H35: =+D35-G35 -> 269488.68 | I35: 342479.11 | J35: =+D35-I35 -> -72990.43 | L35: 269488.68 | M35: 302702.22 | N35: =+L35-M35 -> -33213.537 | O35: 0 | P35: =+L35-O35 -> 269488.68 | Q35: 342479.11 | R35: =+L35-Q35 -> -72990.43
... A38: EBIT - Post Allocations (Stat) | B38: -1 | C38: EBIT | D38: 297551.26 | E38: 237834.38 | F38: =+D38-E38 -> 59716.882 | G38: 0 | H38: =+D38-G38 -> 297551.26 | I38: 131484.96 | J38: =+D38-I38 -> 166066.3 | L38: 297551.26 | M38: 237834.38 | N38: =+L38-M38 -> 59716.882 | O38: 0 | P38: =+L38-O38 -> 297551.26 | Q38: 131484.96 | R38: =+L38-Q38 -> 166066.3
P39: =+L39-O39 -> 0
B40: 1 | C40: Profit and Loss KPI Ratios | P40: =+L40-O40 -> 0
A41: Rehire Recovery % | B41: 1 | C41: Rehire Recovery | D41: 1.1722437 | E41: 1.2984181 | F41: =+D41-E41 -> -0.12617433 | G41: 0 | H41: =+D41-G41 -> 1.1722437 | I41: 1.2007318 | J41: =+D41-I41 -> -0.028488098 | L41: 1.1722437 | M41: 1.2984181 | N41: =+L41-M41 -> -0.12617433 | O41: 0 | P41: =+L41-O41 -> 1.1722437 | Q41: 1.2007318 | R41: =+L41-Q41 -> -0.028488098
A42: Transport Recovery % | B42: 1 | C42: Transport Recovery | D42: 1.1092228 | E42: 1.1418156 | F42: =+D42-E42 -> -0.032592853 | G42: 0 | H42: =+D42-G42 -> 1.1092228 | I42: 0.97283656 | J42: =+D42-I42 -> 0.1363862 | L42: 1.1092228 | M42: 1.1418156 | N42: =+L42-M42 -> -0.032592853 | O42: 0 | P42: =+L42-O42 -> 1.1092228 | Q42: 0.97283656 | R42: =+L42-Q42 -> 0.1363862
A43: Installation Recovery% | B43: 1 | C43: Labour Recovery - Installation | D43: 1.2454228 | E43: 1.3005598 | F43: =+D43-E43 -> -0.055136995 | G43: 0 | H43: =+D43-G43 -> 1.2454228 | I43: 2.0048863 | J43: =+D43-I43 -> -0.7594635 | L43: 1.2454228 | M43: 1.3005598 | N43: =+L43-M43 -> -0.055136995 | O43: 0 | P43: =+L43-O43 -> 1.2454228 | Q43: 2.0048863 | R43: =+L43-Q43 -> -0.7594635
...

Sheet South
A1: CUBE: | C1: Coates:General Ledger | E1: Target Budget FY25 Copy
A2: Financial Entity | C2: All Financial Entities
A3: Plan Measure | C3: Total
D4: =+Parameters!$B$10 -> 2026 | E4: =+Parameters!$B$10 -> 2026 | G4: =+Parameters!$B$10 -> 2026 | I4: =+D4-1 -> 2025 | L4: =+D4 -> 2026 | M4: =+E4 -> 2026 | O4: =+G4 -> 2026 | Q4: =+I4 -> 2025
D5: =+Parameters!$B$9 -> Jul | E5: =+Parameters!$B$9 -> Jul | G5: =+Parameters!$B$9 -> Jul | I5: =+E5 -> Jul | L5: =CONCATENATE(D5," ","YTD") -> Jul YTD | M5: =CONCATENATE(E5," ","YTD") -> Jul YTD | O5: =CONCATENATE(G5," ","YTD") -> Jul YTD | Q5: =CONCATENATE(I5," ","YTD") -> Jul YTD
D6: =+Parameters!B5 -> Actual | E6: =+Parameters!$B$6 -> Target Budget | G6: =+Parameters!$B$7 -> Forecast Current | I6: =+D6 -> Actual | L6: =+D6 -> Actual | M6: =+E6 -> Target Budget | O6: =+G6 -> Forecast Current | Q6: =+I6 -> Actual
D7: =+Lists!G1 -> IS_SOUTH BU | E7: =+D7 -> IS_SOUTH BU | F7: =+E7 -> IS_SOUTH BU | G7: =+F7 -> IS_SOUTH BU | H7: =+G7 -> IS_SOUTH BU | I7: =+H7 -> IS_SOUTH BU | J7: =+I7 -> IS_SOUTH BU | K7: =+J7 -> IS_SOUTH BU | L7: =+K7 -> IS_SOUTH BU | ... R7: =+Q7 -> IS_SOUTH BU
C8: =+Group!$C$8 -> FINANCIAL YEAR 2027 | D8: South - Industrial Solutions
D10: =CONCATENATE($D$5," ","MTD") -> Jul MTD | L10: =CONCATENATE($D$5," ","YTD") -> Jul YTD
D11: Actual | E11: Budget | F11: Var Bud | G11: Forecast | H11: Var Forecast | I11: Last Year | J11: Var LY | L11: Actual | M11: Budget | N11: Var Bud | O11: Forecast | P11: Var Forecast | Q11: Last Year | R11: Var LY
A12: Hire Revenue | B12: -1 | C12: Hire Revenue | D12: 824679.96 | E12: 928423.12 | F12: =+D12-E12 -> -103743.16 | G12: 0 | H12: =+D12-G12 -> 824679.96 | I12: 941618.68 | J12: =+D12-I12 -> -116938.72 | L12: 824679.96 | M12: 928423.12 | N12: =+L12-M12 -> -103743.16 | O12: 0 | P12: =+L12-O12 -> 824679.96 | Q12: 941618.68 | R12: =+L12-Q12 -> -116938.72
A13: Rehire Revenue | B13: -1 | C13: Rehire Revenue | D13: 25414.28 | E13: 15249.781 | F13: =+D13-E13 -> 10164.499 | G13: 0 | H13: =+D13-G13 -> 25414.28 | I13: 15579.96 | J13: =+D13-I13 -> 9834.32 | L13: 25414.28 | M13: 15249.781 | N13: =+L13-M13 -> 10164.499 | O13: 0 | P13: =+L13-O13 -> 25414.28 | Q13: 15579.96 | R13: =+L13-Q13 -> 9834.32
A14: Transport | B14: -1 | C14: Transport Revenue | D14: 38125.82 | E14: 25604.925 | F14: =+D14-E14 -> 12520.895 | G14: 0 | H14: =+D14-G14 -> 38125.82 | I14: 26907.12 | J14: =+D14-I14 -> 11218.7 | L14: 38125.82 | M14: 25604.925 | N14: =+L14-M14 -> 12520.895 | O14: 0 | P14: =+L14-O14 -> 38125.82 | Q14: 26907.12 | R14: =+L14-Q14 -> 11218.7
A15: Other Revenue. | B15: -1 | C15: Other Revenue | D15: 85649.64 | E15: 110444.17 | F15: =+D15-E15 -> -24794.534 | G15: 0 | H15: =+D15-G15 -> 85649.64 | I15: 108997.81 | J15: =+D15-I15 -> -23348.17 | L15: 85649.64 | M15: 110444.17 | N15: =+L15-M15 -> -24794.534 | O15: 0 | P15: =+L15-O15 -> 85649.64 | Q15: 108997.81 | R15: =+L15-Q15 -> -23348.17
A16: Total Combined Revenue | B16: -1 | C16: Total Revenue | D16: 973869.7 | E16: 1079722 | F16: =+D16-E16 -> -105852.3 | G16: 0 | H16: =+D16-G16 -> 973869.7 | I16: 1093103.6 | J16: =+D16-I16 -> -119233.87 | L16: 973869.7 | M16: 1079722 | N16: =+L16-M16 -> -105852.3 | O16: 0 | P16: =+L16-O16 -> 973869.7 | Q16: 1093103.6 | R16: =+L16-Q16 -> -119233.87 | T16: =D16/E16 -> 0.90196338
A17: Total Repairs & Maintenance | B17: 1 | C17: Total Repairs & Maint | D17: 321364.07 | E17: 235825.48 | F17: =+D17-E17 -> 85538.588 | G17: 0 | H17: =+D17-G17 -> 321364.07 | I17: 243428.84 | J17: =+D17-I17 -> 77935.23 | L17: 321364.07 | M17: 235825.48 | N17: =+L17-M17 -> 85538.588 | O17: 0 | P17: =+L17-O17 -> 321364.07 | Q17: 243428.84 | R17: =+L17-Q17 -> 77935.23
A18: Transport Expenses (Stat) | B18: 1 | C18: Transport | D18: 57764.2 | E18: 32342.034 | F18: =+D18-E18 -> 25422.166 | G18: 0 | H18: =+D18-G18 -> 57764.2 | I18: 46775.47 | J18: =+D18-I18 -> 10988.73 | L18: 57764.2 | M18: 32342.034 | N18: =+L18-M18 -> 25422.166 | O18: 0 | P18: =+L18-O18 -> 57764.2 | Q18: 46775.47 | R18: =+L18-Q18 -> 10988.73
A19: Rehire Expenses | B19: 1 | C19: Rehire | D19: 25105.97 | E19: 10971.066 | F19: =+D19-E19 -> 14134.904 | G19: 0 | H19: =+D19-G19 -> 25105.97 | I19: 15787.35 | J19: =+D19-I19 -> 9318.62 | L19: 25105.97 | M19: 10971.066 | N19: =+L19-M19 -> 14134.904 | O19: 0 | P19: =+L19-O19 -> 25105.97 | Q19: 15787.35 | R19: =+L19-Q19 -> 9318.62
A20: Profit/Loss on Sale of Asset | B20: 1 | C20: POSA | D20: 0 | E20: 0 | F20: =+D20-E20 -> 0 | G20: 0 | H20: =+D20-G20 -> 0 | I20: 0 | J20: =+D20-I20 -> 0 | L20: 0 | M20: 0 | N20: =+L20-M20 -> 0 | O20: 0 | P20: =+L20-O20 -> 0 | Q20: 0 | R20: =+L20-Q20 -> 0
A21: Other Direct Costs | B21: 1 | C21: Other Direct Costs | D21: 92383.08 | E21: 127395.25 | F21: =+D21-E21 -> -35012.172 | G21: 0 | H21: =+D21-G21 -> 92383.08 | I21: 128953.87 | J21: =+D21-I21 -> -36570.79 | L21: 92383.08 | M21: 127395.25 | N21: =+L21-M21 -> -35012.172 | O21: 0 | P21: =+L21-O21 -> 92383.08 | Q21: 128953.87 | R21: =+L21-Q21 -> -36570.79
A22: Total Combined Direct Costs (Stat) | B22: 1 | C22: Total Direct Costs | D22: 496617.32 | E22: 406533.83 | F22: =+D22-E22 -> 90083.486 | G22: 0 | H22: =+D22-G22 -> 496617.32 | I22: 434945.53 | J22: =+D22-I22 -> 61671.79 | L22: 496617.32 | M22: 406533.83 | N22: =+L22-M22 -> 90083.486 | O22: 0 | P22: =+L22-O22 -> 496617.32 | Q22: 434945.53 | R22: =+L22-Q22 -> 61671.79 | T22: =D22/E22 -> 1.2215891
A23: Gross Margin - Post Allocations (Stat) | B23: -1 | C23: Gross Margin | D23: 477252.38 | E23: 673188.17 | F23: =+D23-E23 -> -195935.79 | G23: 0 | H23: =+D23-G23 -> 477252.38 | I23: 658158.04 | J23: =+D23-I23 -> -180905.66 | L23: 477252.38 | M23: 673188.17 | N23: =+L23-M23 -> -195935.79 | O23: 0 | P23: =+L23-O23 -> 477252.38 | Q23: 658158.04 | R23: =+L23-Q23 -> -180905.66 | T23: =+D23/D16 -> 0.49005774 | U23: =+E23/E16 -> 0.62348287
A24: Property (Stat) | B24: 1 | C24: Property | D24: 34298.88 | E24: 32353.32 | F24: =+D24-E24 -> 1945.5596 | G24: 0 | H24: =+D24-G24 -> 34298.88 | I24: 27915.87 | J24: =+D24-I24 -> 6383.01 | L24: 34298.88 | M24: 32353.32 | N24: =+L24-M24 -> 1945.5596 | O24: 0 | P24: =+L24-O24 -> 34298.88 | Q24: 27915.87 | R24: =+L24-Q24 -> 6383.01
A25: Direct Staff Costs (Stat) | B25: 1 | C25: Direct Staff | D25: 73980.57 | E25: 89233.636 | F25: =+D25-E25 -> -15253.066 | G25: 0 | H25: =+D25-G25 -> 73980.57 | I25: 94503.34 | J25: =+D25-I25 -> -20522.77 | L25: 73980.57 | M25: 89233.636 | N25: =+L25-M25 -> -15253.066 | O25: 0 | P25: =+L25-O25 -> 73980.57 | Q25: 94503.34 | R25: =+L25-Q25 -> -20522.77
A26: Indirect Staff Costs | B26: 1 | C26: Indirect Staff | D26: 3320.59 | E26: 4567.68 | F26: =+D26-E26 -> -1247.09 | G26: 0 | H26: =+D26-G26 -> 3320.59 | I26: 4102.79 | J26: =+D26-I26 -> -782.2 | L26: 3320.59 | M26: 4567.68 | N26: =+L26-M26 -> -1247.09 | O26: 0 | P26: =+L26-O26 -> 3320.59 | Q26: 4102.79 | R26: =+L26-Q26 -> -782.2
A27: Marketing and Entertainment (BUFR) | B27: 1 | C27: Marketing/Entertainment | D27: 0 | E27: 255.73 | F27: =+D27-E27 -> -255.73 | G27: 0 | H27: =+D27-G27 -> 0 | I27: 0 | J27: =+D27-I27 -> 0 | L27: 0 | M27: 255.73 | N27: =+L27-M27 -> -255.73 | O27: 0 | P27: =+L27-O27 -> 0 | Q27: 0 | R27: =+L27-Q27 -> 0
A28: Telecommunications | B28: 1 | C28: Telecommunications | D28: 1530.83 | E28: 1755.07 | F28: =+D28-E28 -> -224.24 | G28: 0 | H28: =+D28-G28 -> 1530.83 | I28: 1588.42 | J28: =+D28-I28 -> -57.59 | L28: 1530.83 | M28: 1755.07 | N28: =+L28-M28 -> -224.24 | O28: 0 | P28: =+L28-O28 -> 1530.83 | Q28: 1588.42 | R28: =+L28-Q28 -> -57.59
A29: IT & EDP Expenses | B29: 1 | C29: IT&EDP | D29: 1377 | E29: 1436.32 | F29: =+D29-E29 -> -59.32 | G29: 0 | H29: =+D29-G29 -> 1377 | I29: 1392.72 | J29: =+D29-I29 -> -15.72 | L29: 1377 | M29: 1436.32 | N29: =+L29-M29 -> -59.32 | O29: 0 | P29: =+L29-O29 -> 1377 | Q29: 1392.72 | R29: =+L29-Q29 -> -15.72
A30: Travel & Accomodation Expense | B30: 1 | C30: Travel & Accommodation | D30: 12721 | E30: 670.15 | F30: =+D30-E30 -> 12050.85 | G30: 0 | H30: =+D30-G30 -> 12721 | I30: 0 | J30: =+D30-I30 -> 12721 | L30: 12721 | M30: 670.15 | N30: =+L30-M30 -> 12050.85 | O30: 0 | P30: =+L30-O30 -> 12721 | Q30: 0 | R30: =+L30-Q30 -> 12721
A31: Bad Debts | B31: 1 | C31: Bad Debts | D31: 1774.38 | E31: 2030.35 | F31: =+D31-E31 -> -255.97 | G31: 0 | H31: =+D31-G31 -> 1774.38 | I31: 1880.55 | J31: =+D31-I31 -> -106.17 | L31: 1774.38 | M31: 2030.35 | N31: =+L31-M31 -> -255.97 | O31: 0 | P31: =+L31-O31 -> 1774.38 | Q31: 1880.55 | R31: =+L31-Q31 -> -106.17
A32: Branch Admin (Stat) | B32: 1 | C32: Total Branch Administration | D32: 6617.51 | E32: 5384.2677 | F32: =+D32-E32 -> 1233.2423 | G32: 0 | H32: =+D32-G32 -> 6617.51 | I32: 11382.3 | J32: =+D32-I32 -> -4764.79 | L32: 6617.51 | M32: 5384.2677 | N32: =+L32-M32 -> 1233.2423 | O32: 0 | P32: =+L32-O32 -> 6617.51 | Q32: 11382.3 | R32: =+L32-Q32 -> -4764.79
A33: Statutory Cost | B33: 1 | C33: Statutory | D33: 2433.33 | E33: 2433.33 | F33: =+D33-E33 -> 0 | G33: 0 | H33: =+D33-G33 -> 2433.33 | I33: 2358.07 | J33: =+D33-I33 -> 75.26 | L33: 2433.33 | M33: 2433.33 | N33: =+L33-M33 -> 0 | O33: 0 | P33: =+L33-O33 -> 2433.33 | Q33: 2358.07 | R33: =+L33-Q33 -> 75.26
A34: Shared services & Allocated Costs | B34: 1 | C34: Shared services & Allocated Costs | D34: 168871.03 | E34: 158575.28 | F34: =+D34-E34 -> 10295.752 | G34: 0 | H34: =+D34-G34 -> 168871.03 | I34: 204888.91 | J34: =+D34-I34 -> -36017.88 | L34: 168871.03 | M34: 158575.28 | N34: =+L34-M34 -> 10295.752 | O34: 0 | P34: =+L34-O34 -> 168871.03 | Q34: 204888.91 | R34: =+L34-Q34 -> -36017.88
A35: Total Combined Overheads (Stat) | B35: 1 | C35: Total Overheads | D35: 306925.12 | E35: 298695.13 | F35: =+D35-E35 -> 8229.9873 | G35: 0 | H35: =+D35-G35 -> 306925.12 | I35: 350012.97 | J35: =+D35-I35 -> -43087.85 | L35: 306925.12 | M35: 298695.13 | N35: =+L35-M35 -> 8229.9873 | O35: 0 | P35: =+L35-O35 -> 306925.12 | Q35: 350012.97 | R35: =+L35-Q35 -> -43087.85
... A38: EBIT - Post Allocations (Stat) | B38: -1 | C38: EBIT | D38: -24976.05 | E38: 170851.93 | F38: =+D38-E38 -> -195827.98 | G38: 0 | H38: =+D38-G38 -> -24976.05 | I38: 105226.99 | J38: =+D38-I38 -> -130203.04 | L38: -24976.05 | M38: 170851.93 | N38: =+L38-M38 -> -195827.98 | O38: 0 | P38: =+L38-O38 -> -24976.05 | Q38: 105226.99 | R38: =+L38-Q38 -> -130203.04
P39: =+L39-O39 -> 0
B40: 1 | C40: Profit and Loss KPI Ratios | P40: =+L40-O40 -> 0
A41: Rehire Recovery % | B41: 1 | C41: Rehire Recovery | D41: 1.0122803 | E41: 1.39 | F41: =+D41-E41 -> -0.37771965 | G41: 0 | H41: =+D41-G41 -> 1.0122803 | I41: 0.98686353 | J41: =+D41-I41 -> 0.025416813 | L41: 1.0122803 | M41: 1.39 | N41: =+L41-M41 -> -0.37771965 | O41: 0 | P41: =+L41-O41 -> 1.0122803 | Q41: 0.98686353 | R41: =+L41-Q41 -> 0.025416813
A42: Transport Recovery % | B42: 1 | C42: Transport Recovery | D42: 0.66002507 | E42: 0.79169184 | F42: =+D42-E42 -> -0.13166677 | G42: 0 | H42: =+D42-G42 -> 0.66002507 | I42: 0.57523997 | J42: =+D42-I42 -> 0.084785097 | L42: 0.66002507 | M42: 0.79169184 | N42: =+L42-M42 -> -0.13166677 | O42: 0 | P42: =+L42-O42 -> 0.66002507 | Q42: 0.57523997 | R42: =+L42-Q42 -> 0.084785097
A43: Installation Recovery% | B43: 1 | C43: Labour Recovery - Installation | D43: -531201555169280 | E43: 1.255 | F43: =+D43-E43 -> -5.3120156e+14 | G43: 0 | H43: =+D43-G43 -> -531201555169280 | I43: 0 | J43: =+D43-I43 -> -531201555169280 | L43: -531201555169280 | M43: 1.255 | N43: =+L43-M43 -> -5.3120156e+14 | O43: 0 | P43: =+L43-O43 -> -531201555169280 | Q43: 0 | R43: =+L43-Q43 -> -531201555169280
...

Sheet West
A1: CUBE: | C1: Coates:General Ledger | E1: Target Budget FY25 Copy
A2: Financial Entity | C2: All Financial Entities
A3: Plan Measure | C3: Total
D4: =+Parameters!$B$10 -> 2026 | E4: =+Parameters!$B$10 -> 2026 | G4: =+Parameters!$B$10 -> 2026 | I4: =+D4-1 -> 2025 | L4: =+D4 -> 2026 | M4: =+E4 -> 2026 | O4: =+G4 -> 2026 | Q4: =+I4 -> 2025
D5: =+Parameters!$B$9 -> Jul | E5: =+Parameters!$B$9 -> Jul | G5: =+Parameters!$B$9 -> Jul | I5: =+E5 -> Jul | L5: =CONCATENATE(D5," ","YTD") -> Jul YTD | M5: =CONCATENATE(E5," ","YTD") -> Jul YTD | O5: =CONCATENATE(G5," ","YTD") -> Jul YTD | Q5: =CONCATENATE(I5," ","YTD") -> Jul YTD
D6: =+Parameters!B5 -> Actual | E6: =+Parameters!$B$6 -> Target Budget | G6: =+Parameters!$B$7 -> Forecast Current | I6: =+D6 -> Actual | L6: =+D6 -> Actual | M6: =+E6 -> Target Budget | O6: =+G6 -> Forecast Current | Q6: =+I6 -> Actual
D7: =+Lists!I1 -> IS_WEST BU | E7: =+D7 -> IS_WEST BU | F7: =+E7 -> IS_WEST BU | G7: =+F7 -> IS_WEST BU | H7: =+G7 -> IS_WEST BU | I7: =+H7 -> IS_WEST BU | J7: =+I7 -> IS_WEST BU | K7: =+J7 -> IS_WEST BU | L7: =+K7 -> IS_WEST BU | ... R7: =+Q7 -> IS_WEST BU
C8: =+Group!$C$8 -> FINANCIAL YEAR 2027 | D8: West - Industrial Solutions
D10: =CONCATENATE($D$5," ","MTD") -> Jul MTD | L10: =CONCATENATE($D$5," ","YTD") -> Jul YTD
D11: Actual | E11: Budget | F11: Var Bud | G11: Forecast | H11: Var Forecast | I11: Last Year | J11: Var LY | L11: Actual | M11: Budget | N11: Var Bud | O11: Forecast | P11: Var Forecast | Q11: Last Year | R11: Var LY
A12: Hire Revenue | B12: -1 | C12: Hire Revenue | D12: 1207307.5 | E12: 1368532.3 | F12: =+D12-E12 -> -161224.84 | G12: 0 | H12: =+D12-G12 -> 1207307.5 | I12: 983381.41 | J12: =+D12-I12 -> 223926.09 | L12: 1207307.5 | M12: 1368532.3 | N12: =+L12-M12 -> -161224.84 | O12: 0 | P12: =+L12-O12 -> 1207307.5 | Q12: 983381.41 | R12: =+L12-Q12 -> 223926.09
A13: Rehire Revenue | B13: -1 | C13: Rehire Revenue | D13: 899605.44 | E13: 426735.14 | F13: =+D13-E13 -> 472870.3 | G13: 0 | H13: =+D13-G13 -> 899605.44 | I13: 337729.88 | J13: =+D13-I13 -> 561875.56 | L13: 899605.44 | M13: 426735.14 | N13: =+L13-M13 -> 472870.3 | O13: 0 | P13: =+L13-O13 -> 899605.44 | Q13: 337729.88 | R13: =+L13-Q13 -> 561875.56
A14: Transport | B14: -1 | C14: Transport Revenue | D14: 174264.93 | E14: 134573 | F14: =+D14-E14 -> 39691.933 | G14: 0 | H14: =+D14-G14 -> 174264.93 | I14: 92540.49 | J14: =+D14-I14 -> 81724.44 | L14: 174264.93 | M14: 134573 | N14: =+L14-M14 -> 39691.933 | O14: 0 | P14: =+L14-O14 -> 174264.93 | Q14: 92540.49 | R14: =+L14-Q14 -> 81724.44
A15: Other Revenue. | B15: -1 | C15: Other Revenue | D15: 656002.38 | E15: 952243.52 | F15: =+D15-E15 -> -296241.14 | G15: 0 | H15: =+D15-G15 -> 656002.38 | I15: 575410.84 | J15: =+D15-I15 -> 80591.54 | L15: 656002.38 | M15: 952243.52 | N15: =+L15-M15 -> -296241.14 | O15: 0 | P15: =+L15-O15 -> 656002.38 | Q15: 575410.84 | R15: =+L15-Q15 -> 80591.54
A16: Total Combined Revenue | B16: -1 | C16: Total Revenue | D16: 2937180.2 | E16: 2882084 | F16: =+D16-E16 -> 55096.25 | G16: 0 | H16: =+D16-G16 -> 2937180.2 | I16: 1989062.6 | J16: =+D16-I16 -> 948117.63 | L16: 2937180.2 | M16: 2882084 | N16: =+L16-M16 -> 55096.25 | O16: 0 | P16: =+L16-O16 -> 2937180.2 | Q16: 1989062.6 | R16: =+L16-Q16 -> 948117.63 | T16: =D16/E16 -> 1.0191168
A17: Total Repairs & Maintenance | B17: 1 | C17: Total Repairs & Maint | D17: 239713.13 | E17: 206675.14 | F17: =+D17-E17 -> 33037.994 | G17: 0 | H17: =+D17-G17 -> 239713.13 | I17: 178152.33 | J17: =+D17-I17 -> 61560.8 | L17: 239713.13 | M17: 206675.14 | N17: =+L17-M17 -> 33037.994 | O17: 0 | P17: =+L17-O17 -> 239713.13 | Q17: 178152.33 | R17: =+L17-Q17 -> 61560.8
A18: Transport Expenses (Stat) | B18: 1 | C18: Transport | D18: 150100.24 | E18: 104709.07 | F18: =+D18-E18 -> 45391.174 | G18: 0 | H18: =+D18-G18 -> 150100.24 | I18: 88634.83 | J18: =+D18-I18 -> 61465.41 | L18: 150100.24 | M18: 104709.07 | N18: =+L18-M18 -> 45391.174 | O18: 0 | P18: =+L18-O18 -> 150100.24 | Q18: 88634.83 | R18: =+L18-Q18 -> 61465.41
A19: Rehire Expenses | B19: 1 | C19: Rehire | D19: 697268.29 | E19: 379231.45 | F19: =+D19-E19 -> 318036.84 | G19: 0 | H19: =+D19-G19 -> 697268.29 | I19: 307029.18 | J19: =+D19-I19 -> 390239.11 | L19: 697268.29 | M19: 379231.45 | N19: =+L19-M19 -> 318036.84 | O19: 0 | P19: =+L19-O19 -> 697268.29 | Q19: 307029.18 | R19: =+L19-Q19 -> 390239.11
A20: Profit/Loss on Sale of Asset | B20: 1 | C20: POSA | D20: 0 | E20: 0 | F20: =+D20-E20 -> 0 | G20: 0 | H20: =+D20-G20 -> 0 | I20: 0 | J20: =+D20-I20 -> 0 | L20: 0 | M20: 0 | N20: =+L20-M20 -> 0 | O20: 0 | P20: =+L20-O20 -> 0 | Q20: 0 | R20: =+L20-Q20 -> 0
A21: Other Direct Costs | B21: 1 | C21: Other Direct Costs | D21: 565377.24 | E21: 784046.36 | F21: =+D21-E21 -> -218669.12 | G21: 0 | H21: =+D21-G21 -> 565377.24 | I21: 507255.48 | J21: =+D21-I21 -> 58121.76 | L21: 565377.24 | M21: 784046.36 | N21: =+L21-M21 -> -218669.12 | O21: 0 | P21: =+L21-O21 -> 565377.24 | Q21: 507255.48 | R21: =+L21-Q21 -> 58121.76
A22: Total Combined Direct Costs (Stat) | B22: 1 | C22: Total Direct Costs | D22: 1652458.9 | E22: 1474662 | F22: =+D22-E22 -> 177796.89 | G22: 0 | H22: =+D22-G22 -> 1652458.9 | I22: 1081071.8 | J22: =+D22-I22 -> 571387.08 | L22: 1652458.9 | M22: 1474662 | N22: =+L22-M22 -> 177796.89 | O22: 0 | P22: =+L22-O22 -> 1652458.9 | Q22: 1081071.8 | R22: =+L22-Q22 -> 571387.08 | T22: =D22/E22 -> 1.1205679
A23: Gross Margin - Post Allocations (Stat) | B23: -1 | C23: Gross Margin | D23: 1284721.4 | E23: 1407422 | F23: =+D23-E23 -> -122700.64 | G23: 0 | H23: =+D23-G23 -> 1284721.4 | I23: 907990.8 | J23: =+D23-I23 -> 376730.55 | L23: 1284721.4 | M23: 1407422 | N23: =+L23-M23 -> -122700.64 | O23: 0 | P23: =+L23-O23 -> 1284721.4 | Q23: 907990.8 | R23: =+L23-Q23 -> 376730.55 | T23: =+D23/D16 -> 0.43739956 | U23: =+E23/E16 -> 0.48833483
A24: Property (Stat) | B24: 1 | C24: Property | D24: 52313.87 | E24: 40452.74 | F24: =+D24-E24 -> 11861.13 | G24: 0 | H24: =+D24-G24 -> 52313.87 | I24: 33238.5 | J24: =+D24-I24 -> 19075.37 | L24: 52313.87 | M24: 40452.74 | N24: =+L24-M24 -> 11861.13 | O24: 0 | P24: =+L24-O24 -> 52313.87 | Q24: 33238.5 | R24: =+L24-Q24 -> 19075.37
A25: Direct Staff Costs (Stat) | B25: 1 | C25: Direct Staff | D25: 163515.44 | E25: 160692.2 | F25: =+D25-E25 -> 2823.2387 | G25: 0 | H25: =+D25-G25 -> 163515.44 | I25: 162840.73 | J25: =+D25-I25 -> 674.71 | L25: 163515.44 | M25: 160692.2 | N25: =+L25-M25 -> 2823.2387 | O25: 0 | P25: =+L25-O25 -> 163515.44 | Q25: 162840.73 | R25: =+L25-Q25 -> 674.71
A26: Indirect Staff Costs | B26: 1 | C26: Indirect Staff | D26: 9527.61 | E26: 8407.0342 | F26: =+D26-E26 -> 1120.5758 | G26: 0 | H26: =+D26-G26 -> 9527.61 | I26: 16321.23 | J26: =+D26-I26 -> -6793.62 | L26: 9527.61 | M26: 8407.0342 | N26: =+L26-M26 -> 1120.5758 | O26: 0 | P26: =+L26-O26 -> 9527.61 | Q26: 16321.23 | R26: =+L26-Q26 -> -6793.62
A27: Marketing and Entertainment (BUFR) | B27: 1 | C27: Marketing/Entertainment | D27: 0 | E27: 44.5525 | F27: =+D27-E27 -> -44.5525 | G27: 0 | H27: =+D27-G27 -> 0 | I27: 15.68 | J27: =+D27-I27 -> -15.68 | L27: 0 | M27: 44.5525 | N27: =+L27-M27 -> -44.5525 | O27: 0 | P27: =+L27-O27 -> 0 | Q27: 15.68 | R27: =+L27-Q27 -> -15.68
A28: Telecommunications | B28: 1 | C28: Telecommunications | D28: 3528.76 | E28: 3268.3283 | F28: =+D28-E28 -> 260.43167 | G28: 0 | H28: =+D28-G28 -> 3528.76 | I28: 3847.22 | J28: =+D28-I28 -> -318.46 | L28: 3528.76 | M28: 3268.3283 | N28: =+L28-M28 -> 260.43167 | O28: 0 | P28: =+L28-O28 -> 3528.76 | Q28: 3847.22 | R28: =+L28-Q28 -> -318.46
A29: IT & EDP Expenses | B29: 1 | C29: IT&EDP | D29: 1027 | E29: 780.69083 | F29: =+D29-E29 -> 246.30917 | G29: 0 | H29: =+D29-G29 -> 1027 | I29: 570 | J29: =+D29-I29 -> 457 | L29: 1027 | M29: 780.69083 | N29: =+L29-M29 -> 246.30917 | O29: 0 | P29: =+L29-O29 -> 1027 | Q29: 570 | R29: =+L29-Q29 -> 457
A30: Travel & Accomodation Expense | B30: 1 | C30: Travel & Accommodation | D30: 2402.01 | E30: 4771.6225 | F30: =+D30-E30 -> -2369.6125 | G30: 0 | H30: =+D30-G30 -> 2402.01 | I30: 5165.94 | J30: =+D30-I30 -> -2763.93 | L30: 2402.01 | M30: 4771.6225 | N30: =+L30-M30 -> -2369.6125 | O30: 0 | P30: =+L30-O30 -> 2402.01 | Q30: 5165.94 | R30: =+L30-Q30 -> -2763.93
A31: Bad Debts | B31: 1 | C31: Bad Debts | D31: 5115.35 | E31: 4481.5981 | F31: =+D31-E31 -> 633.7519 | G31: 0 | H31: =+D31-G31 -> 5115.35 | I31: 3420.47 | J31: =+D31-I31 -> 1694.88 | L31: 5115.35 | M31: 4481.5981 | N31: =+L31-M31 -> 633.7519 | O31: 0 | P31: =+L31-O31 -> 5115.35 | Q31: 3420.47 | R31: =+L31-Q31 -> 1694.88
A32: Branch Admin (Stat) | B32: 1 | C32: Total Branch Administration | D32: 8287.91 | E32: 7335.9809 | F32: =+D32-E32 -> 951.92913 | G32: 0 | H32: =+D32-G32 -> 8287.91 | I32: 10464.9 | J32: =+D32-I32 -> -2176.99 | L32: 8287.91 | M32: 7335.9809 | N32: =+L32-M32 -> 951.92913 | O32: 0 | P32: =+L32-O32 -> 8287.91 | Q32: 10464.9 | R32: =+L32-Q32 -> -2176.99
A33: Statutory Cost | B33: 1 | C33: Statutory | D33: 1398.1 | E33: 1398.0992 | F33: =+D33-E33 -> 0.00083333333 | G33: 0 | H33: =+D33-G33 -> 1398.1 | I33: 1399.47 | J33: =+D33-I33 -> -1.37 | L33: 1398.1 | M33: 1398.0992 | N33: =+L33-M33 -> 0.00083333333 | O33: 0 | P33: =+L33-O33 -> 1398.1 | Q33: 1399.47 | R33: =+L33-Q33 -> -1.37
